Workbook

Sheet HƯỚNG_DẪN
A1: GOMA – DỮ LIỆU GAME THẺ BÀI (v5, bản thô demo: 8 tướng × 3 phẩm chất)
A2: CẢNH BÁO | B2: Mọi số chỉ số, skill, ngân sách trong file là SỐ NHÁP để HỖ TRỢ, chưa cân. Nhiều buff nhỏ gộp lại rất mạnh (ví dụ tank có khiên, hồi, nội tại hồi và khiêu khích gần như bất tử), nên cân bằng thật phải dựa vào chơi thử và chỉnh số.
A3: Trạng thái | B3: Claude đã sinh nháp chỉ số, skill, nội tại cho 8 vai theo khung vai trò. Anh đổi tên, viết gia vị, sửa số rồi gửi lại để làm bản chơi được.
A5: ANH CẦN LÀM
A6: 1. NHÂN_VẬT | B6: Đặt tên thật cho 8 tướng (đang là tên tạm). Vai trò đã gán sẵn: 2 Tank, 2 Vật lý, 1 Phép, 2 Hỗ trợ, 1 Sát thủ. Đổi nếu muốn.
A7: 2. SKILL_MÔ_TẢ | B7: Đặt lại tên skill, viết cột 'Gia vị'. Đổi số ở đây thì phải sửa SKILL_THÀNH_PHẦN cho khớp (game đọc số từ SKILL_THÀNH_PHẦN).
A8: 3. Rà số | B8: Xem CHỈ_SỐ_TRẮNG (cột Kiểm khung), SKILL_THÀNH_PHẦN, KIỂM_NGÂN_SÁCH. Sửa số ở ô vàng.
A9: 4. ẢNH_NHÂN_VẬT | B9: Ghi tên file ảnh khi có.
A10: 5. LUẬT_VÀ_QUYẾT_ĐỊNH | B10: Đọc để biết cái gì đã chốt, tạm, chưa chốt, đang treo. Lọc theo cột Trạng thái.
A12: MÀU Ô
A13: Vàng nhạt, chữ xanh | B13: Ô anh có thể sửa.
A14: Xanh lá nhạt | B14: Công thức tự tính. Gõ đè được nếu muốn chỉnh tay.
A15: Xám đậm | B15: Ô không áp dụng.
A17: CÁC SHEET
A18: LUẬT_VÀ_QUYẾT_ĐỊNH | B18: Toàn bộ luật trận, phạm vi demo, quyết định, vấn đề đang treo. Cùng nội dung với file md thiết kế.
A19: KHUNG_VAI_TRÒ | B19: Chuẩn Trắng, khoảng chỉ số và ngân sách skill của 5 vai trò.
A20: CHỈ_SỐ_TRẮNG / HỆ_SỐ_PHẨM_CHẤT / CHỈ_SỐ_TÍNH | B20: Chỉ số bản Trắng → tự tính Xanh lá, Xanh dương (Tím, Đỏ để sau). Hệ số là SỐ GIẢ.
A21: SKILL_MÔ_TẢ | B21: Tên và mô tả skill, nội tại (phần gia vị).
A22: SKILL_THÀNH_PHẦN | B22: Cơ chế thật: mỗi skill gồm nhiều thành phần (sát thương, khiên, hồi, trạng thái...), có số mục tiêu, độ lớn, xác suất theo phẩm chất.
A23: KIỂM_NGÂN_SÁCH | B23: So điểm sức mạnh skill với khung vai trò.
A24: HIỆU_ỨNG | B24: Trạng thái dùng chung. Khiêu khích và Làm chậm là đề xuất của Claude.
A26: LUẬT ĐÃ CHỐT (tóm tắt)
A27: Nộ | B27: Bắt đầu 50. Đánh trúng +30 cho người đánh. Bị đánh +10 (kể cả bị né, bị skill). Né thì người đánh không +30. Đủ 100 xả skill rồi về 0. Skill không chí mạng, có thể bị né.
A28: Đội hình | B28: 2 hàng × 3 ô, tối đa 5 tướng. Đòn thường: hàng trước trước, random trong hàng. Tối đa 15 lượt.
A29: Phẩm chất demo | B29: Trắng: skill gốc. Xanh lá: tăng chỉ số và độ lớn skill. Xanh dương: thêm nội tại, hiệu ứng phụ xuất hiện. Tím, Đỏ để bản sau.
A31: SỐ GIẢ / GIẢ ĐỊNH CẦN BIẾT
A32: Ngân sách | B32: 1 điểm = 1% máu chuẩn, sát thương, hồi, khiên quy đổi ngang giá. Chưa kiểm bằng mô phỏng.
A33: Số khác ví dụ của anh | B33: Khiên Tank 12% (anh nêu 5%), hồi Hỗ trợ 18-22% (anh nêu 5%): vì ngân sách khung. Muốn dùng số của anh thì sửa ở SKILL_THÀNH_PHẦN.
A34: Xác suất hiệu ứng | B34: 10% / 15% (bước nhảy lớn hơn 5% / 7%) để người chơi cảm nhận được. Sửa nếu anh muốn giữ 5%.

Sheet LUẬT_VÀ_QUYẾT_ĐỊNH
A1: LUẬT VÀ QUYẾT ĐỊNH – cái gì đã chốt, tạm, chưa chốt, đang treo
A2: Đã chốt = anh quyết. Tạm = Claude đề xuất hoặc số tạm. Chưa chốt = chưa bàn xong. Treo = đã nêu phương án, anh chưa chọn.
A4: Nhóm | B4: Mục | C4: Nội dung | D4: Trạng thái | E4: Ghi chú
A5: 1. Dự án và time-box | B5: Mục đích | C5: Game thẻ bài gacha đánh theo lượt, tướng là đồng nghiệp công ty, làm cho vui, khoảng 20 người chơi. Anh coi đây là thử thách và case study. | D5: Đã chốt
A6: 1. Dự án và time-box | B6: Hạn | C6: Bản thô chơi được đến tối 07/10/2026, chỉ khoảng 3-4 giờ làm thật. Anh tự tạo áp lực để xem mình làm được gì. | D6: Đã chốt
A7: 1. Dự án và time-box | B7: Mở rộng | C7: Thêm tối đa 24 giờ nếu bản thô đạt kỳ vọng người chơi. | D7: Đã chốt
A8: 1. Dự án và time-box | B8: Tiêu chí đạt | C8: Trong 24 giờ có ít nhất 8/20 người thử, ít nhất 50% chơi xong trận đầu, ít nhất 3 người chơi lại lần 2. Đạt thì mở thêm 24 giờ, không đạt thì đóng băng và ghi bài học. | D8: Tạm | E8: Mặc định của Claude, anh chưa xác nhận số. Người chơi lại lần 2 là thước thật vì lần đầu bị ảo do tò mò khi thấy mặt mình, sếp trong game.
A9: 1. Dự án và time-box | B9: Thứ tự cắt nếu trễ | C9: Mini-game thứ hai, rồi trùm, rồi giảm số tướng từ 8 xuống 6. Không kéo dài hạn, không cắt giờ ngủ để bù. | D9: Tạm | E9: Đề xuất của Claude.
A10: 1. Dự án và time-box | B10: Dòng 'game vui' | C10: Màn vào game có một dòng nói đây chỉ là game vui, để tránh mích lòng. | D10: Đã chốt
A11: 1. Dự án và time-box | B11: Báo người trong game | C11: Cho những người xuất hiện (nhất là nhân vật sếp) xem trước khi phát cho cả nhóm. | D11: Tạm | E11: Đề xuất của Claude.
A12: 1. Dự án và time-box | B12: Không xếp theo chức vụ | C12: Sếp hay nhân viên đều có đủ 5 phẩm chất, độ mạnh không theo chức vụ. | D12: Đã chốt
A13: 1. Dự án và time-box | B13: Xác suất quay như nhau | C13: Mọi người có cùng xác suất ra, độ hiếm nằm ở phẩm chất. | D13: Tạm | E13: Đề xuất của Claude.
A14: 2. Phạm vi bản demo | B14: Tướng và phẩm chất | C14: 8 tướng × 3 phẩm chất (Trắng, Xanh lá, Xanh dương). Tím và Đỏ để bản sau, vì vào game đã thấy Đỏ thì mất vui. | D14: Đã chốt
A15: 2. Phạm vi bản demo | B15: Vai trò 8 tướng | C15: 2 Tank, 2 Vật lý, 1 Phép, 2 Hỗ trợ, 1 Sát thủ. Tank A là Thủ kho Hiếu. | D15: Tạm | E15: Claude gán, anh đổi được.
A16: 2. Phạm vi bản demo | B16: Nội dung chặng | C16: 1 chặng vài trận, 3 loại quái và 1 trùm. | D16: Tạm | E16: Quái và trùm là ai chưa chốt (gợi ý: chuột, mèo hoang, thảm mốc, trùm Khách khó tính).
A17: 2. Phạm vi bản demo | B17: Mini-game | C17: 2 mini-game đơn giản, 1 mini-game nếu thiếu giờ. Mini-game đầu ở lượt 1. | D17: Tạm
A18: 2. Phạm vi bản demo | B18: Gacha demo | C18: Ra thẳng phẩm chất: Trắng 65%, Xanh lá 27%, Xanh dương 8%. Tặng khoảng 10 lượt quay và 3 tướng Trắng khởi đầu. Quay trùng đổi thành 1 lượt quay. Không có mảnh, bảo hiểm. | D18: Tạm | E18: Số tạm để chạy được.
A19: 2. Phạm vi bản demo | B19: Kỹ thuật | C19: HTML 1 file, lưu tiến trình bằng localStorage. | D19: Tạm
A20: 2. Phạm vi bản demo | B20: Nền tảng | C20: Chơi trên điện thoại (màn dọc) hay máy tính. | D20: Chưa chốt | E20: Quyết định tỷ lệ nền và cách xếp 2 hàng tướng.
A21: 2. Phạm vi bản demo | B21: Không làm ở demo | C21: Cơ chế mảnh nâng cấp, nâng cấp auto, PvP, phẩm chất Tím và Đỏ. | D21: Tạm
A22: 3. Luật trận (PvE) | B22: Số lượt | C22: Tối đa 15 lượt. | D22: Đã chốt
A23: 3. Luật trận (PvE) | B23: Thắng thua | C23: Toàn đội tướng chết thì thua. Hết 15 lượt chưa diệt hết quái cũng thua. | D23: Đã chốt
A24: 3. Luật trận (PvE) | B24: PvP | C24: Để trống. Dự kiến hết lượt thì so tổng máu, hòa thì đội có tướng ra đòn đầu ở lượt 1 thắng. | D24: Chưa chốt | E24: Anh bảo còn xa.
A25: 3. Luật trận (PvE) | B25: Đội hình | C25: 2 hàng × 3 ô = 6 vị trí, tối đa 5 tướng. | D25: Đã chốt
A26: 3. Luật trận (PvE) | B26: Thứ tự ra đòn | C26: Tốc độ cao ra trước, tính lại mỗi lượt (đã cộng buff/debuff), so số lẻ không làm tròn. | D26: Đã chốt
A27: 3. Luật trận (PvE) | B27: Gacha ẩn | C27: Chỉ khi hai đơn vị bằng nhau chính xác mới quay ngẫu nhiên. Mỗi lượt quay lại, người chơi không thấy. | D27: Đã chốt | E27: Nên ghi log kết quả quay để phát lại khi test (đề xuất của Claude).
A28: 3. Luật trận (PvE) | B28: Chọn mục tiêu đòn thường | C28: Hàng trước trước, random trong hàng, hết hàng trước mới tới hàng sau. | D28: Đã chốt
A29: 3. Luật trận (PvE) | B29: Skill nhắm hàng đã hết người | C29: Random 1 đối tượng còn sống khác của đội địch. | D29: Đã chốt
A30: 3. Luật trận (PvE) | B30: Nộ khởi đầu | C30: 50 nộ mỗi trận, cả tướng lẫn quái. | D30: Đã chốt
A31: 3. Luật trận (PvE) | B31: Cộng và dùng nộ | C31: Đánh trúng +30 cho người đánh. Bị đánh +10 (kể cả bị né, bị skill). Đủ 100 thì xả skill, xả xong về 0 (phần dư mất). | D31: Đã chốt
A32: 3. Luật trận (PvE) | B32: Né | C32: Né thành công: người né +10 nộ, người đánh không được +30, không mất máu. | D32: Đã chốt
A33: 3. Luật trận (PvE) | B33: Skill | C33: Không chí mạng, có thể bị né. Skill nhiều mục tiêu: mỗi mục tiêu tự xét né và +10 nộ riêng, người xả về 0 một lần. | D33: Đã chốt
A34: 3. Luật trận (PvE) | B34: Hồi máu | C34: Hồi/lượt là số cố định, hồi ngay sau khi chính đơn vị đó ra đòn xong, đơn vị chết không hồi. Hồi theo %: tính trên máu tối đa của người được hồi. | D34: Đã chốt
A35: 3. Luật trận (PvE) | B35: Khiên | C35: Mỗi lần xả skill tạo 1 khiên (% máu tối đa của người xả). Sát thương trừ khiên trước. Vỡ khi bị đánh vượt giá trị khiên hoặc sau 2 lượt. | D35: Đã chốt | E35: Xả lại khi khiên cũ còn: làm mới, không cộng dồn (mặc định tạm, anh chưa xác nhận).
A36: 3. Luật trận (PvE) | B36: 'Chậm 1 lượt' | C36: Nếu lượt đó chưa ra đòn thì mất đòn. Đã ra đòn rồi thì chỉ chịu hiệu ứng phụ (trừ nộ, giảm tốc). | D36: Đã chốt
A37: 3. Luật trận (PvE) | B37: Cách đếm thời lượng | C37: Hiệu ứng N lượt: lượt hiện tại tính là lượt thứ nhất. Nếu người nhận đã ra đòn rồi thì coi như mất 1 lượt, chưa ra đòn thì được lượt này cộng lượt kế (với hiệu ứng 2 lượt). | D37: Đã chốt | E37: Anh nêu cho Điên tiết. Claude áp dụng chung cho mọi hiệu ứng N lượt (khớp với khiên hết sau 2 lượt), anh sửa nếu khác.
A38: 3. Luật trận (PvE) | B38: 10 chỉ số | C38: Máu, Công, Thủ, Tốc độ, Hồi máu/lượt, Né, Chính xác, Tỷ lệ chí mạng, Sát thương chí mạng, Kháng chí mạng. Né và tỷ lệ chí mạng giữ dưới 10%. | D38: Đã chốt
A39: 3. Luật trận (PvE) | B39: Công thức né, chí mạng | C39: Né hiệu dụng = Né − Chính xác (sàn 0%, trần 60%). Chí mạng hiệu dụng = Tỷ lệ chí mạng − Kháng chí mạng (sàn 0%, trần 75%). Sát thương chí mạng mặc định 150%. | D39: Tạm | E39: Anh đồng ý tạm, sẽ chỉnh khi mất cân bằng.
A40: 3. Luật trận (PvE) | B40: Công thức sát thương | C40: Công × 100 / (100 + Thủ). Skill Trắng gây 200% công lên 1 mục tiêu. | D40: Tạm
A41: 3. Luật trận (PvE) | B41: Khiêu khích | C41: Địch buộc đánh người khiêu khích (đòn thường và skill 1 mục tiêu), 1 lượt. Skill nhiều mục tiêu không bị ảnh hưởng. Nhiều người khiêu khích: địch random giữa họ. Choáng hoặc đóng băng người khiêu khích thì mất tác dụng. | D41: Tạm | E41: Anh đã chốt là có hiệu ứng này; quy tắc chi tiết là đề xuất của Claude.
...

Sheet KHUNG_VAI_TRÒ
A1: KHUNG VAI TRÒ (đã chốt với anh, số là điểm xuất phát)
A2: Hệ số tính trên 'chuẩn Trắng'. Sửa ô vàng thì CHỈ_SỐ_TRẮNG tự kiểm lại 'Ngoài khung / OK'.
B4: Máu | C4: Công | D4: Thủ | E4: Tốc độ | F4: Hồi máu
A5: Chuẩn Trắng | B5: 1000 | C5: 100 | D5: 40 | E5: 100 | F5: 15
A6: Sức mạnh thô = Máu × (100 + Thủ)/100 × Công, chuẩn = 1,00.
A8: Vai trò | B8: Máu min (×) | C8: Máu max (×) | D8: Công min (×) | E8: Công max (×) | F8: Thủ min (×) | G8: Thủ max (×) | H8: Tốc độ min (×) | I8: Tốc độ max (×) | J8: Kiểu skill | K8: Ngân sách mỗi lần xả (điểm) | L8: Ghi chú
A9: Tank | B9: 1.3 | C9: 1.5 | D9: 0.6 | E9: 0.8 | F9: 1.3 | G9: 1.7 | H9: 0.85 | I9: 0.95 | J9: khiên, hồi, giảm sát thương, khiêu khích | K9: 60 | L9: Xả nhiều hơn hàng sau, mỗi lần nhẹ hơn.
A10: Vật lý | B10: 0.75 | C10: 0.9 | D10: 1.3 | E10: 1.5 | F10: 0.8 | G10: 1 | H10: 0.95 | I10: 1.05 | J10: 1 mục tiêu, dame lớn | K10: 100 | L10: 100 điểm = ×2,0 công lên 1 mục tiêu.
A11: Phép | B11: 0.8 | C11: 0.95 | D11: 1 | E11: 1.15 | F11: 0.8 | G11: 1 | H11: 1 | I11: 1.1 | J11: 2 đến toàn bộ mục tiêu, dame nhỏ + hiệu ứng nhẹ | K11: 110 | L11: Tổng tối đa = 100 + 10 điểm mỗi mục tiêu thêm.
A12: Hỗ trợ | B12: 0.9 | C12: 1.1 | D12: 0.6 | E12: 0.8 | F12: 0.9 | G12: 1.1 | H12: 1.05 | I12: 1.15 | J12: hồi, buff, hồi nộ | K12: 100 | L12: Sức mạnh thô thấp có chủ ý, bù bằng giá trị skill.
A13: Sát thủ | B13: 0.7 | C13: 0.85 | D13: 1.2 | E13: 1.4 | F13: 0.6 | G13: 0.8 | H13: 1.15 | I13: 1.3 | J13: 1 mục tiêu hàng sau hoặc máu thấp | K13: 90 | L13: Tốc độ cao, mong manh.
A14: Tank-Vật lý | B14: 1.1 | C14: 1.3 | D14: 0.8 | E14: 1 | F14: 1.1 | G14: 1.4 | H14: 0.8 | I14: 0.95 | J14: 2 mục tiêu liền nhau (hàng trước + ngay sau), dame vừa + choáng, tự buff Điên tiết | K14: 120 | L14: Lai Tank và Vật lý. Anh đã xác nhận.
A15: Phép-Buff | B15: 0.8 | C15: 1 | D15: 0.75 | E15: 1 | F15: 0.8 | G15: 1.1 | H15: 1.1 | I15: 1.2 | J15: 2 mục tiêu, dame nhỏ + khống chế (Ru ngủ), nội tại hồi sinh | K15: 110 | L15: Lai Phép và khống chế/hỗ trợ. Anh đã xác nhận.
A17: Ngân sách: 1 điểm = 1% máu chuẩn (100 điểm = 20% máu chuẩn = 200 sát thương). Quy đổi sát thương, hồi, khiên ngang giá là GIẢ ĐỊNH, chưa kiểm bằng mô phỏng.
A18: Hiệu ứng trạng thái, buff, hồi nộ chưa quy đổi được ra điểm, KIỂM_NGÂN_SÁCH chỉ đếm số thành phần chưa tính.

Sheet NHÂN_VẬT
A1: NHÂN VẬT – danh sách tướng
A2: 8 dòng đầu đã đặt sẵn vai trò theo khung, tên là TẠM (anh đổi). Tên chỉ gõ ở đây, các sheet khác tự lấy.
A4: Mã NV | B4: Tên nhân vật | C4: Tên hiển thị trong game | D4: Vai trò chiến đấu | E4: Hàng đứng ưu tiên | F4: Tiểu sử ngắn | G4: Câu thoại khi xả skill | H4: Ghi chú
A6: NV01 | B6: HCM-THỦ KHO HIẾU | D6: Tank | E6: Hàng trước | F6: THỦ KHO VÀO LÀM ĐỦ 2 NĂM , GÌ CŨNG BIẾT CHỈ LÀ BIẾT KHÔNG SÂU , LẦM LẦM LÌ LÌ MÀ LẠI HAY QUÊN | G6: HUYNH ĐỆ À - CỨ BÌNH TỈNH ĐI ĐÓ MÀ
A7: NV02 | B7: HN-PHỤ KHO HƯNG | D7: Tank | E7: Hàng trước | F7: THANH NIÊN LÀM LÂU NĂM , SỨC DÀI VAI RỘNG ,19 TUỔI VỚI KHUÔN MẶT CỦA KẺ 30 TUỔI , QUY TẮC VÀNG LÀM 5 LẦN ẮT SẼ SAI ÍT NHẤT 1 LẦN ,SAI LẦN NÀO THÌ CHƯA BIẾT THÔI | G7: CÓ GÌ CỨ ĐÁNH TUI , MÀ NHỚ CHỪA MẶT TUI RA NHA
A8: NV03 | B8: HCM-PHỤ KHO VŨ | D8: Vật lý | E8: Hàng sau | F8: MỚI VÀO LÀM ĐƯỢC VÀI THÁNG ,GÌ CŨNG CHƯA BIẾT , NHIỆT TÌNH NHƯNG HAY NHIỆT TÌNH NHẦM CHỖ ,SAI NHIỀU MÀ ĐÚNG CŨNG NHIỀU | G8: TẤT CẢ TRÁNH RA - ĐỂ TA LO TẤT
A9: NV04 | B9: HCM-SALE THẢO | D9: Vật lý | E9: Hàng sau | F9: SALE LÀM CŨNG HƠN 1 NĂM , CHỐT ĐƠN CŨNG NHIỀU MÀ TẠCH CŨNG QUÁ TRỜI , LÀ SALE ANH CẢ TRONG CHI NHÁNH HCM , HAY CƯỜI HÌ HÌ , LÀM VIỆC RẤT NGUYÊN TẮC . | G9: CHO XIN TÍ HUYẾT VỀ XÀO VỚI GIÁ NHÉ BẠN HIỀN
A10: NV05 | B10: HCM-SALE DƯƠNG | D10: Phép | E10: Hàng sau | F10: SALE LÀM HƠN 1 NĂM , NHIỆT TÌNH ,TƯ VẤN KHÁCH BẤT CHẤP NGÀY GIỜ HAY NẮNG MƯA , CHẬM NHƯNG HAY ĂN CHẮC ,CHỐT TOÀN ĐƠN NGON | G10: CHẾT MÀY NÈ !!!! Ý Ý XIN LỖI
A11: NV06 | B11: HCM-SALE DUYÊN | D11: Hỗ trợ | E11: Hàng sau | F11: LÀ 1 NGƯỜI NĂNG ĐỘNG ,CA HÁT NHÃY MÚA ĐỀU THÔNG THẠO , SỐ HƠI XUI ,ĐƠN CHỐT CHƯA NHIỀU "TOÀN GẶP ÂM BINH " | G11: CỨ ĐÁNH TẸT GA ,TRÀ CHIỀU ĐỂ CHỊ LO TẤT .
A12: NV07 | B12: HCM-KẾ TOÁN THU | D12: Hỗ trợ | E12: Hàng sau | F12: LÀ NHÂN VẬT KHÁ LÂU NĂM TRONG CÔNG TY ,LÀM KẾ TOÁN CHI NHÁNH HCM , AI CŨNG PHẢI QUA TAY CÔ NÀNG , BIẾT ĐIỀU THÌ MỚI XUÔNG ĐƯỢC , À ĐANG GIẢM CÂN ,BỚT DỤ ĐỒ ĂN NHÉ . | G12: ANH EM CỨ CHIẾN , CHỌC ĐIÊN THÌ ĐỂ CHỊ LO.
A13: NV08 | B13: HCM-SALE NHÂN | D13: Sát thủ | E13: Hàng sau | F13: BEST SALE HCM , CHIỀU KHÁCH VÔ ĐỐI NHƯNG CHỐT ĐƠN CŨNG HOÀNH TRÁNG ,ĐƠN TO LÀ ANH CÓ MẶT | G13: ANH BẠN À , HỞ SƯỜN RỒI KÌA HẸ HẸ !
A14: NV09 | B14: HCM-PHỤ KHO ANH LÂM | D14: TANK-VẬT LÝ | E14: Hàng trước | F14: TỔ TRƯỞNG KHO , LÀ 1 NHÂN VẬT LÂU NĂM TẠI KHO HCM , BIẾT NHIỀU THỨ MÀ KHÔNG PHẢI AI CŨNG BIẾT , CHỈ LÀ LỚN TUỔI MẮT YẾU VÀ HAY QUÊN . | G14: TẤT CẢ TRÁNH RA XE NÂNG ĐẾN RỒI ĐÂY
A15: NV11 | B15: HCM- BÍCH THÍCH CHAN | D15: Phép-BUFF | E15: Hàng sau | F15: THANH NIÊN VÀO LÀM VỚI CHỨC VỤ THIẾT KẾ NHƯNG LẠI RẤT THÍCH CỰ VÀ GÂY THÙ CHUỐC OÁNH ( HAY CÒN GỌI LÀ CHAN ) , ĐỪNG CÓ XÍCH MÍT VỚI Ả NHÉ , SỐNG KHÔNG THỌ ĐÂU | G15: TẤT CẢ CHỈ LÀ HIỂU LẦM THÔI , NGỦ ĐI BÉ BÌ À. | H15: THÊM 1 TRẠNG THÁI MỚI LÀ RU NGỦ ( BUFF CHO ĐỐI THỦ DẠNG BẤT LỢI , MẤT 1 LƯỢT ĐÁNH, GIẢM 5% TỐC ĐỘ VÀ GIẢM 5% TẤN CÔNG CỦA ĐỐI THỦ )
A16: NV12
A17: NV13
A18: NV14
A19: NV15
A20: NV16
A21: NV17
A22: NV18
A23: NV19
A24: NV20
A25: NV21
A26: NV22
A27: NV23
... A34: NV30

Sheet CHỈ_SỐ_TRẮNG
A1: CHỈ SỐ GỐC – phẩm chất TRẮNG (Claude sinh nháp theo khung vai trò, anh sửa)
A2: Cột N, O tự tính: sức mạnh thô và kiểm có nằm trong khung vai trò không. Tỷ lệ gõ dạng % (ví dụ 3%).
A4: Mã NV | B4: Tên nhân vật | C4: Vai trò | D4: Máu | E4: Công | F4: Thủ | G4: Tốc độ | H4: Hồi máu / lượt | I4: Né (%) | J4: Chính xác (%) | K4: Tỷ lệ chí mạng (%) | L4: Sát thương chí mạng (%) | M4: Kháng chí mạng (%) | N4: Sức mạnh thô (×chuẩn) | O4: Kiểm khung vai trò
A6: =NHÂN_VẬT!$A$6 -> NV01 | B6: =IF(NHÂN_VẬT!$B$6="","",NHÂN_VẬT!$B$6) -> HCM-THỦ KHO HIẾU | C6: =IF(NHÂN_VẬT!$D$6="","",NHÂN_VẬT!$D$6) -> Tank | D6: 1500 | E6: 65 | F6: 64 | G6: 88 | H6: 24 | I6: 0.02 | J6: 0.02 | K6: 0.03 | L6: 1.5 | M6: 0.06 | N6: =IF(OR(D6="",E6="",F6=""),"",D6*(100+F6)/100*E6/(KHUNG_VAI_TRÒ!$B$5*(100+KHUNG_VAI_TRÒ!$D$5)/100*KHUNG_VAI_TRÒ!$C$5)) -> 1.1421429 | O6: =IF(OR(D6="",E6="",F6="",G6="",C6=""),"",IFERROR(IF(AND(D6/KHUNG_VAI_TRÒ!$B$5>=INDEX(KHUNG_VAI_TRÒ!$B$9:$B$15,MATCH($C6,KHUNG_VAI_TRÒ!$A$9:$A$15,0))-0.0001,D6/KHUNG_VAI_TRÒ!$B$5<=INDEX(KHUNG_VAI_TRÒ!$C$9:$C$15,MATCH($C6,KHUNG_VAI_TRÒ!$A$9:$A$15,0))+0.0001,E6/KHUNG_VAI_TRÒ!$C$5>=INDEX(KHUNG_VAI_TRÒ!$D$9:$D$15,MATCH($C6,KHUNG_VAI_TRÒ!$A$9:$A$15,0))-0.0001,E6/KHUNG_VAI_TRÒ!$C$5<=INDEX(KHUNG_VAI_TRÒ!$E$9:$E$15,MATCH($C6,KHUNG_VAI_TRÒ!$A$9:$A$15,0))+0.0001,F6/KHUNG_VAI_TRÒ!$D$5>=INDEX(KHUNG_VAI_TRÒ!$F$9:$F$15,MATCH($C6,KHUNG_VAI_TRÒ!$A$9:$A$15,0))-0.0001,F6/KHUNG_VAI_TRÒ!$D$5<=INDEX(KHUNG_VAI_TRÒ!$G$9:$G$15,MATCH($C6,KHUNG_VAI_TRÒ!$A$9:$A$15,0))+0.0001,G6/KHUNG_VAI_TRÒ!$E$5>=INDEX(KHUNG_VAI_TRÒ!$H$9:$H$15,MATCH($C6,KHUNG_VAI_TRÒ!$A$9:$A$15,0))-0.0001,G6/KHUNG_VAI_TRÒ!$E$5<=INDEX(KHUNG_VAI_TRÒ!$I$9:$I$15,MATCH($C6,KHUNG_VAI_TRÒ!$A$9:$A$15,0))+0.0001),"OK","Ngoài khung"),"Vai trò?")) -> OK
A7: =NHÂN_VẬT!$A$7 -> NV02 | B7: =IF(NHÂN_VẬT!$B$7="","",NHÂN_VẬT!$B$7) -> HN-PHỤ KHO HƯNG | C7: =IF(NHÂN_VẬT!$D$7="","",NHÂN_VẬT!$D$7) -> Tank | D7: 1350 | E7: 75 | F7: 56 | G7: 92 | H7: 20 | I7: 0.03 | J7: 0.02 | K7: 0.03 | L7: 1.5 | M7: 0.05 | N7: =IF(OR(D7="",E7="",F7=""),"",D7*(100+F7)/100*E7/(KHUNG_VAI_TRÒ!$B$5*(100+KHUNG_VAI_TRÒ!$D$5)/100*KHUNG_VAI_TRÒ!$C$5)) -> 1.1282143 | O7: =IF(OR(D7="",E7="",F7="",G7="",C7=""),"",IFERROR(IF(AND(D7/KHUNG_VAI_TRÒ!$B$5>=INDEX(KHUNG_VAI_TRÒ!$B$9:$B$15,MATCH($C7,KHUNG_VAI_TRÒ!$A$9:$A$15,0))-0.0001,D7/KHUNG_VAI_TRÒ!$B$5<=INDEX(KHUNG_VAI_TRÒ!$C$9:$C$15,MATCH($C7,KHUNG_VAI_TRÒ!$A$9:$A$15,0))+0.0001,E7/KHUNG_VAI_TRÒ!$C$5>=INDEX(KHUNG_VAI_TRÒ!$D$9:$D$15,MATCH($C7,KHUNG_VAI_TRÒ!$A$9:$A$15,0))-0.0001,E7/KHUNG_VAI_TRÒ!$C$5<=INDEX(KHUNG_VAI_TRÒ!$E$9:$E$15,MATCH($C7,KHUNG_VAI_TRÒ!$A$9:$A$15,0))+0.0001,F7/KHUNG_VAI_TRÒ!$D$5>=INDEX(KHUNG_VAI_TRÒ!$F$9:$F$15,MATCH($C7,KHUNG_VAI_TRÒ!$A$9:$A$15,0))-0.0001,F7/KHUNG_VAI_TRÒ!$D$5<=INDEX(KHUNG_VAI_TRÒ!$G$9:$G$15,MATCH($C7,KHUNG_VAI_TRÒ!$A$9:$A$15,0))+0.0001,G7/KHUNG_VAI_TRÒ!$E$5>=INDEX(KHUNG_VAI_TRÒ!$H$9:$H$15,MATCH($C7,KHUNG_VAI_TRÒ!$A$9:$A$15,0))-0.0001,G7/KHUNG_VAI_TRÒ!$E$5<=INDEX(KHUNG_VAI_TRÒ!$I$9:$I$15,MATCH($C7,KHUNG_VAI_TRÒ!$A$9:$A$15,0))+0.0001),"OK","Ngoài khung"),"Vai trò?")) -> OK
A8: =NHÂN_VẬT!$A$8 -> NV03 | B8: =IF(NHÂN_VẬT!$B$8="","",NHÂN_VẬT!$B$8) -> HCM-PHỤ KHO VŨ | C8: =IF(NHÂN_VẬT!$D$8="","",NHÂN_VẬT!$D$8) -> Vật lý | D8: 820 | E8: 140 | F8: 36 | G8: 97 | H8: 10 | I8: 0.03 | J8: 0.04 | K8: 0.06 | L8: 1.6 | M8: 0.01 | N8: =IF(OR(D8="",E8="",F8=""),"",D8*(100+F8)/100*E8/(KHUNG_VAI_TRÒ!$B$5*(100+KHUNG_VAI_TRÒ!$D$5)/100*KHUNG_VAI_TRÒ!$C$5)) -> 1.1152 | O8: =IF(OR(D8="",E8="",F8="",G8="",C8=""),"",IFERROR(IF(AND(D8/KHUNG_VAI_TRÒ!$B$5>=INDEX(KHUNG_VAI_TRÒ!$B$9:$B$15,MATCH($C8,KHUNG_VAI_TRÒ!$A$9:$A$15,0))-0.0001,D8/KHUNG_VAI_TRÒ!$B$5<=INDEX(KHUNG_VAI_TRÒ!$C$9:$C$15,MATCH($C8,KHUNG_VAI_TRÒ!$A$9:$A$15,0))+0.0001,E8/KHUNG_VAI_TRÒ!$C$5>=INDEX(KHUNG_VAI_TRÒ!$D$9:$D$15,MATCH($C8,KHUNG_VAI_TRÒ!$A$9:$A$15,0))-0.0001,E8/KHUNG_VAI_TRÒ!$C$5<=INDEX(KHUNG_VAI_TRÒ!$E$9:$E$15,MATCH($C8,KHUNG_VAI_TRÒ!$A$9:$A$15,0))+0.0001,F8/KHUNG_VAI_TRÒ!$D$5>=INDEX(KHUNG_VAI_TRÒ!$F$9:$F$15,MATCH($C8,KHUNG_VAI_TRÒ!$A$9:$A$15,0))-0.0001,F8/KHUNG_VAI_TRÒ!$D$5<=INDEX(KHUNG_VAI_TRÒ!$G$9:$G$15,MATCH($C8,KHUNG_VAI_TRÒ!$A$9:$A$15,0))+0.0001,G8/KHUNG_VAI_TRÒ!$E$5>=INDEX(KHUNG_VAI_TRÒ!$H$9:$H$15,MATCH($C8,KHUNG_VAI_TRÒ!$A$9:$A$15,0))-0.0001,G8/KHUNG_VAI_TRÒ!$E$5<=INDEX(KHUNG_VAI_TRÒ!$I$9:$I$15,MATCH($C8,KHUNG_VAI_TRÒ!$A$9:$A$15,0))+0.0001),"OK","Ngoài khung"),"Vai trò?")) -> OK
A9: =NHÂN_VẬT!$A$9 -> NV04 | B9: =IF(NHÂN_VẬT!$B$9="","",NHÂN_VẬT!$B$9) -> HCM-SALE THẢO | C9: =IF(NHÂN_VẬT!$D$9="","",NHÂN_VẬT!$D$9) -> Vật lý | D9: 880 | E9: 130 | F9: 34 | G9: 101 | H9: 10 | I9: 0.03 | J9: 0.05 | K9: 0.05 | L9: 1.55 | M9: 0.01 | N9: =IF(OR(D9="",E9="",F9=""),"",D9*(100+F9)/100*E9/(KHUNG_VAI_TRÒ!$B$5*(100+KHUNG_VAI_TRÒ!$D$5)/100*KHUNG_VAI_TRÒ!$C$5)) -> 1.0949714 | O9: =IF(OR(D9="",E9="",F9="",G9="",C9=""),"",IFERROR(IF(AND(D9/KHUNG_VAI_TRÒ!$B$5>=INDEX(KHUNG_VAI_TRÒ!$B$9:$B$15,MATCH($C9,KHUNG_VAI_TRÒ!$A$9:$A$15,0))-0.0001,D9/KHUNG_VAI_TRÒ!$B$5<=INDEX(KHUNG_VAI_TRÒ!$C$9:$C$15,MATCH($C9,KHUNG_VAI_TRÒ!$A$9:$A$15,0))+0.0001,E9/KHUNG_VAI_TRÒ!$C$5>=INDEX(KHUNG_VAI_TRÒ!$D$9:$D$15,MATCH($C9,KHUNG_VAI_TRÒ!$A$9:$A$15,0))-0.0001,E9/KHUNG_VAI_TRÒ!$C$5<=INDEX(KHUNG_VAI_TRÒ!$E$9:$E$15,MATCH($C9,KHUNG_VAI_TRÒ!$A$9:$A$15,0))+0.0001,F9/KHUNG_VAI_TRÒ!$D$5>=INDEX(KHUNG_VAI_TRÒ!$F$9:$F$15,MATCH($C9,KHUNG_VAI_TRÒ!$A$9:$A$15,0))-0.0001,F9/KHUNG_VAI_TRÒ!$D$5<=INDEX(KHUNG_VAI_TRÒ!$G$9:$G$15,MATCH($C9,KHUNG_VAI_TRÒ!$A$9:$A$15,0))+0.0001,G9/KHUNG_VAI_TRÒ!$E$5>=INDEX(KHUNG_VAI_TRÒ!$H$9:$H$15,MATCH($C9,KHUNG_VAI_TRÒ!$A$9:$A$15,0))-0.0001,G9/KHUNG_VAI_TRÒ!$E$5<=INDEX(KHUNG_VAI_TRÒ!$I$9:$I$15,MATCH($C9,KHUNG_VAI_TRÒ!$A$9:$A$15,0))+0.0001),"OK","Ngoài khung"),"Vai trò?")) -> OK
A10: =NHÂN_VẬT!$A$10 -> NV05 | B10: =IF(NHÂN_VẬT!$B$10="","",NHÂN_VẬT!$B$10) -> HCM-SALE DƯƠNG | C10: =IF(NHÂN_VẬT!$D$10="","",NHÂN_VẬT!$D$10) -> Phép | D10: 880 | E10: 108 | F10: 36 | G10: 105 | H10: 12 | I10: 0.04 | J10: 0.04 | K10: 0.04 | L10: 1.5 | M10: 0.02 | N10: =IF(OR(D10="",E10="",F10=""),"",D10*(100+F10)/100*E10/(KHUNG_VAI_TRÒ!$B$5*(100+KHUNG_VAI_TRÒ!$D$5)/100*KHUNG_VAI_TRÒ!$C$5)) -> 0.92324571 | O10: =IF(OR(D10="",E10="",F10="",G10="",C10=""),"",IFERROR(IF(AND(D10/KHUNG_VAI_TRÒ!$B$5>=INDEX(KHUNG_VAI_TRÒ!$B$9:$B$15,MATCH($C10,KHUNG_VAI_TRÒ!$A$9:$A$15,0))-0.0001,D10/KHUNG_VAI_TRÒ!$B$5<=INDEX(KHUNG_VAI_TRÒ!$C$9:$C$15,MATCH($C10,KHUNG_VAI_TRÒ!$A$9:$A$15,0))+0.0001,E10/KHUNG_VAI_TRÒ!$C$5>=INDEX(KHUNG_VAI_TRÒ!$D$9:$D$15,MATCH($C10,KHUNG_VAI_TRÒ!$A$9:$A$15,0))-0.0001,E10/KHUNG_VAI_TRÒ!$C$5<=INDEX(KHUNG_VAI_TRÒ!$E$9:$E$15,MATCH($C10,KHUNG_VAI_TRÒ!$A$9:$A$15,0))+0.0001,F10/KHUNG_VAI_TRÒ!$D$5>=INDEX(KHUNG_VAI_TRÒ!$F$9:$F$15,MATCH($C10,KHUNG_VAI_TRÒ!$A$9:$A$15,0))-0.0001,F10/KHUNG_VAI_TRÒ!$D$5<=INDEX(KHUNG_VAI_TRÒ!$G$9:$G$15,MATCH($C10,KHUNG_VAI_TRÒ!$A$9:$A$15,0))+0.0001,G10/KHUNG_VAI_TRÒ!$E$5>=INDEX(KHUNG_VAI_TRÒ!$H$9:$H$15,MATCH($C10,KHUNG_VAI_TRÒ!$A$9:$A$15,0))-0.0001,G10/KHUNG_VAI_TRÒ!$E$5<=INDEX(KHUNG_VAI_TRÒ!$I$9:$I$15,MATCH($C10,KHUNG_VAI_TRÒ!$A$9:$A$15,0))+0.0001),"OK","Ngoài khung"),"Vai trò?")) -> OK
A11: =NHÂN_VẬT!$A$11 -> NV06 | B11: =IF(NHÂN_VẬT!$B$11="","",NHÂN_VẬT!$B$11) -> HCM-SALE DUYÊN | C11: =IF(NHÂN_VẬT!$D$11="","",NHÂN_VẬT!$D$11) -> Hỗ trợ | D11: 1000 | E11: 70 | F11: 40 | G11: 109 | H11: 18 | I11: 0.04 | J11: 0.03 | K11: 0.03 | L11: 1.5 | M11: 0.03 | N11: =IF(OR(D11="",E11="",F11=""),"",D11*(100+F11)/100*E11/(KHUNG_VAI_TRÒ!$B$5*(100+KHUNG_VAI_TRÒ!$D$5)/100*KHUNG_VAI_TRÒ!$C$5)) -> 0.7 | O11: =IF(OR(D11="",E11="",F11="",G11="",C11=""),"",IFERROR(IF(AND(D11/KHUNG_VAI_TRÒ!$B$5>=INDEX(KHUNG_VAI_TRÒ!$B$9:$B$15,MATCH($C11,KHUNG_VAI_TRÒ!$A$9:$A$15,0))-0.0001,D11/KHUNG_VAI_TRÒ!$B$5<=INDEX(KHUNG_VAI_TRÒ!$C$9:$C$15,MATCH($C11,KHUNG_VAI_TRÒ!$A$9:$A$15,0))+0.0001,E11/KHUNG_VAI_TRÒ!$C$5>=INDEX(KHUNG_VAI_TRÒ!$D$9:$D$15,MATCH($C11,KHUNG_VAI_TRÒ!$A$9:$A$15,0))-0.0001,E11/KHUNG_VAI_TRÒ!$C$5<=INDEX(KHUNG_VAI_TRÒ!$E$9:$E$15,MATCH($C11,KHUNG_VAI_TRÒ!$A$9:$A$15,0))+0.0001,F11/KHUNG_VAI_TRÒ!$D$5>=INDEX(KHUNG_VAI_TRÒ!$F$9:$F$15,MATCH($C11,KHUNG_VAI_TRÒ!$A$9:$A$15,0))-0.0001,F11/KHUNG_VAI_TRÒ!$D$5<=INDEX(KHUNG_VAI_TRÒ!$G$9:$G$15,MATCH($C11,KHUNG_VAI_TRÒ!$A$9:$A$15,0))+0.0001,G11/KHUNG_VAI_TRÒ!$E$5>=INDEX(KHUNG_VAI_TRÒ!$H$9:$H$15,MATCH($C11,KHUNG_VAI_TRÒ!$A$9:$A$15,0))-0.0001,G11/KHUNG_VAI_TRÒ!$E$5<=INDEX(KHUNG_VAI_TRÒ!$I$9:$I$15,MATCH($C11,KHUNG_VAI_TRÒ!$A$9:$A$15,0))+0.0001),"OK","Ngoài khung"),"Vai trò?")) -> OK
A12: =NHÂN_VẬT!$A$12 -> NV07 | B12: =IF(NHÂN_VẬT!$B$12="","",NHÂN_VẬT!$B$12) -> HCM-KẾ TOÁN THU | C12: =IF(NHÂN_VẬT!$D$12="","",NHÂN_VẬT!$D$12) -> Hỗ trợ | D12: 950 | E12: 75 | F12: 44 | G12: 113 | H12: 16 | I12: 0.04 | J12: 0.03 | K12: 0.03 | L12: 1.5 | M12: 0.03 | N12: =IF(OR(D12="",E12="",F12=""),"",D12*(100+F12)/100*E12/(KHUNG_VAI_TRÒ!$B$5*(100+KHUNG_VAI_TRÒ!$D$5)/100*KHUNG_VAI_TRÒ!$C$5)) -> 0.73285714 | O12: =IF(OR(D12="",E12="",F12="",G12="",C12=""),"",IFERROR(IF(AND(D12/KHUNG_VAI_TRÒ!$B$5>=INDEX(KHUNG_VAI_TRÒ!$B$9:$B$15,MATCH($C12,KHUNG_VAI_TRÒ!$A$9:$A$15,0))-0.0001,D12/KHUNG_VAI_TRÒ!$B$5<=INDEX(KHUNG_VAI_TRÒ!$C$9:$C$15,MATCH($C12,KHUNG_VAI_TRÒ!$A$9:$A$15,0))+0.0001,E12/KHUNG_VAI_TRÒ!$C$5>=INDEX(KHUNG_VAI_TRÒ!$D$9:$D$15,MATCH($C12,KHUNG_VAI_TRÒ!$A$9:$A$15,0))-0.0001,E12/KHUNG_VAI_TRÒ!$C$5<=INDEX(KHUNG_VAI_TRÒ!$E$9:$E$15,MATCH($C12,KHUNG_VAI_TRÒ!$A$9:$A$15,0))+0.0001,F12/KHUNG_VAI_TRÒ!$D$5>=INDEX(KHUNG_VAI_TRÒ!$F$9:$F$15,MATCH($C12,KHUNG_VAI_TRÒ!$A$9:$A$15,0))-0.0001,F12/KHUNG_VAI_TRÒ!$D$5<=INDEX(KHUNG_VAI_TRÒ!$G$9:$G$15,MATCH($C12,KHUNG_VAI_TRÒ!$A$9:$A$15,0))+0.0001,G12/KHUNG_VAI_TRÒ!$E$5>=INDEX(KHUNG_VAI_TRÒ!$H$9:$H$15,MATCH($C12,KHUNG_VAI_TRÒ!$A$9:$A$15,0))-0.0001,G12/KHUNG_VAI_TRÒ!$E$5<=INDEX(KHUNG_VAI_TRÒ!$I$9:$I$15,MATCH($C12,KHUNG_VAI_TRÒ!$A$9:$A$15,0))+0.0001),"OK","Ngoài khung"),"Vai trò?")) -> OK
A13: =NHÂN_VẬT!$A$13 -> NV08 | B13: =IF(NHÂN_VẬT!$B$13="","",NHÂN_VẬT!$B$13) -> HCM-SALE NHÂN | C13: =IF(NHÂN_VẬT!$D$13="","",NHÂN_VẬT!$D$13) -> Sát thủ | D13: 760 | E13: 130 | F13: 28 | G13: 121 | H13: 8 | I13: 0.06 | J13: 0.06 | K13: 0.08 | L13: 1.65 | M13: 0 | N13: =IF(OR(D13="",E13="",F13=""),"",D13*(100+F13)/100*E13/(KHUNG_VAI_TRÒ!$B$5*(100+KHUNG_VAI_TRÒ!$D$5)/100*KHUNG_VAI_TRÒ!$C$5)) -> 0.90331429 | O13: =IF(OR(D13="",E13="",F13="",G13="",C13=""),"",IFERROR(IF(AND(D13/KHUNG_VAI_TRÒ!$B$5>=INDEX(KHUNG_VAI_TRÒ!$B$9:$B$15,MATCH($C13,KHUNG_VAI_TRÒ!$A$9:$A$15,0))-0.0001,D13/KHUNG_VAI_TRÒ!$B$5<=INDEX(KHUNG_VAI_TRÒ!$C$9:$C$15,MATCH($C13,KHUNG_VAI_TRÒ!$A$9:$A$15,0))+0.0001,E13/KHUNG_VAI_TRÒ!$C$5>=INDEX(KHUNG_VAI_TRÒ!$D$9:$D$15,MATCH($C13,KHUNG_VAI_TRÒ!$A$9:$A$15,0))-0.0001,E13/KHUNG_VAI_TRÒ!$C$5<=INDEX(KHUNG_VAI_TRÒ!$E$9:$E$15,MATCH($C13,KHUNG_VAI_TRÒ!$A$9:$A$15,0))+0.0001,F13/KHUNG_VAI_TRÒ!$D$5>=INDEX(KHUNG_VAI_TRÒ!$F$9:$F$15,MATCH($C13,KHUNG_VAI_TRÒ!$A$9:$A$15,0))-0.0001,F13/KHUNG_VAI_TRÒ!$D$5<=INDEX(KHUNG_VAI_TRÒ!$G$9:$G$15,MATCH($C13,KHUNG_VAI_TRÒ!$A$9:$A$15,0))+0.0001,G13/KHUNG_VAI_TRÒ!$E$5>=INDEX(KHUNG_VAI_TRÒ!$H$9:$H$15,MATCH($C13,KHUNG_VAI_TRÒ!$A$9:$A$15,0))-0.0001,G13/KHUNG_VAI_TRÒ!$E$5<=INDEX(KHUNG_VAI_TRÒ!$I$9:$I$15,MATCH($C13,KHUNG_VAI_TRÒ!$A$9:$A$15,0))+0.0001),"OK","Ngoài khung"),"Vai trò?")) -> OK
A14: =NHÂN_VẬT!$A$14 -> NV09 | B14: =IF(NHÂN_VẬT!$B$14="","",NHÂN_VẬT!$B$14) -> HCM-PHỤ KHO ANH LÂM | C14: =IF(NHÂN_VẬT!$D$14="","",NHÂN_VẬT!$D$14) -> TANK-VẬT LÝ | D14: 1200 | E14: 90 | F14: 50 | G14: 85 | H14: 20 | I14: 0.03 | J14: 0.03 | K14: 0.04 | L14: 1.5 | M14: 0.04 | N14: =IF(OR(D14="",E14="",F14=""),"",D14*(100+F14)/100*E14/(KHUNG_VAI_TRÒ!$B$5*(100+KHUNG_VAI_TRÒ!$D$5)/100*KHUNG_VAI_TRÒ!$C$5)) -> 1.1571429 | O14: =IF(OR(D14="",E14="",F14="",G14="",C14=""),"",IFERROR(IF(AND(D14/KHUNG_VAI_TRÒ!$B$5>=INDEX(KHUNG_VAI_TRÒ!$B$9:$B$15,MATCH($C14,KHUNG_VAI_TRÒ!$A$9:$A$15,0))-0.0001,D14/KHUNG_VAI_TRÒ!$B$5<=INDEX(KHUNG_VAI_TRÒ!$C$9:$C$15,MATCH($C14,KHUNG_VAI_TRÒ!$A$9:$A$15,0))+0.0001,E14/KHUNG_VAI_TRÒ!$C$5>=INDEX(KHUNG_VAI_TRÒ!$D$9:$D$15,MATCH($C14,KHUNG_VAI_TRÒ!$A$9:$A$15,0))-0.0001,E14/KHUNG_VAI_TRÒ!$C$5<=INDEX(KHUNG_VAI_TRÒ!$E$9:$E$15,MATCH($C14,KHUNG_VAI_TRÒ!$A$9:$A$15,0))+0.0001,F14/KHUNG_VAI_TRÒ!$D$5>=INDEX(KHUNG_VAI_TRÒ!$F$9:$F$15,MATCH($C14,KHUNG_VAI_TRÒ!$A$9:$A$15,0))-0.0001,F14/KHUNG_VAI_TRÒ!$D$5<=INDEX(KHUNG_VAI_TRÒ!$G$9:$G$15,MATCH($C14,KHUNG_VAI_TRÒ!$A$9:$A$15,0))+0.0001,G14/KHUNG_VAI_TRÒ!$E$5>=INDEX(KHUNG_VAI_TRÒ!$H$9:$H$15,MATCH($C14,KHUNG_VAI_TRÒ!$A$9:$A$15,0))-0.0001,G14/KHUNG_VAI_TRÒ!$E$5<=INDEX(KHUNG_VAI_TRÒ!$I$9:$I$15,MATCH($C14,KHUNG_VAI_TRÒ!$A$9:$A$15,0))+0.0001),"OK","Ngoài khung"),"Vai trò?")) -> OK
A15: =NHÂN_VẬT!$A$15 -> NV11 | B15: =IF(NHÂN_VẬT!$B$15="","",NHÂN_VẬT!$B$15) -> HCM- BÍCH THÍCH CHAN | C15: =IF(NHÂN_VẬT!$D$15="","",NHÂN_VẬT!$D$15) -> Phép-BUFF | D15: 900 | E15: 85 | F15: 38 | G15: 117 | H15: 14 | I15: 0.04 | J15: 0.04 | K15: 0.04 | L15: 1.5 | M15: 0.02 | N15: =IF(OR(D15="",E15="",F15=""),"",D15*(100+F15)/100*E15/(KHUNG_VAI_TRÒ!$B$5*(100+KHUNG_VAI_TRÒ!$D$5)/100*KHUNG_VAI_TRÒ!$C$5)) -> 0.75407143 | O15: =IF(OR(D15="",E15="",F15="",G15="",C15=""),"",IFERROR(IF(AND(D15/KHUNG_VAI_TRÒ!$B$5>=INDEX(KHUNG_VAI_TRÒ!$B$9:$B$15,MATCH($C15,KHUNG_VAI_TRÒ!$A$9:$A$15,0))-0.0001,D15/KHUNG_VAI_TRÒ!$B$5<=INDEX(KHUNG_VAI_TRÒ!$C$9:$C$15,MATCH($C15,KHUNG_VAI_TRÒ!$A$9:$A$15,0))+0.0001,E15/KHUNG_VAI_TRÒ!$C$5>=INDEX(KHUNG_VAI_TRÒ!$D$9:$D$15,MATCH($C15,KHUNG_VAI_TRÒ!$A$9:$A$15,0))-0.0001,E15/KHUNG_VAI_TRÒ!$C$5<=INDEX(KHUNG_VAI_TRÒ!$E$9:$E$15,MATCH($C15,KHUNG_VAI_TRÒ!$A$9:$A$15,0))+0.0001,F15/KHUNG_VAI_TRÒ!$D$5>=INDEX(KHUNG_VAI_TRÒ!$F$9:$F$15,MATCH($C15,KHUNG_VAI_TRÒ!$A$9:$A$15,0))-0.0001,F15/KHUNG_VAI_TRÒ!$D$5<=INDEX(KHUNG_VAI_TRÒ!$G$9:$G$15,MATCH($C15,KHUNG_VAI_TRÒ!$A$9:$A$15,0))+0.0001,G15/KHUNG_VAI_TRÒ!$E$5>=INDEX(KHUNG_VAI_TRÒ!$H$9:$H$15,MATCH($C15,KHUNG_VAI_TRÒ!$A$9:$A$15,0))-0.0001,G15/KHUNG_VAI_TRÒ!$E$5<=INDEX(KHUNG_VAI_TRÒ!$I$9:$I$15,MATCH($C15,KHUNG_VAI_TRÒ!$A$9:$A$15,0))+0.0001),"OK","Ngoài khung"),"Vai trò?")) -> OK
A16: =NHÂN_VẬT!$A$16 -> NV12 | B16: =IF(NHÂN_VẬT!$B$16="","",NHÂN_VẬT!$B$16) | C16: =IF(NHÂN_VẬT!$D$16="","",NHÂN_VẬT!$D$16) | N16: =IF(OR(D16="",E16="",F16=""),"",D16*(100+F16)/100*E16/(KHUNG_VAI_TRÒ!$B$5*(100+KHUNG_VAI_TRÒ!$D$5)/100*KHUNG_VAI_TRÒ!$C$5)) | O16: =IF(OR(D16="",E16="",F16="",G16="",C16=""),"",IFERROR(IF(AND(D16/KHUNG_VAI_TRÒ!$B$5>=INDEX(KHUNG_VAI_TRÒ!$B$9:$B$15,MATCH($C16,KHUNG_VAI_TRÒ!$A$9:$A$15,0))-0.0001,D16/KHUNG_VAI_TRÒ!$B$5<=INDEX(KHUNG_VAI_TRÒ!$C$9:$C$15,MATCH($C16,KHUNG_VAI_TRÒ!$A$9:$A$15,0))+0.0001,E16/KHUNG_VAI_TRÒ!$C$5>=INDEX(KHUNG_VAI_TRÒ!$D$9:$D$15,MATCH($C16,KHUNG_VAI_TRÒ!$A$9:$A$15,0))-0.0001,E16/KHUNG_VAI_TRÒ!$C$5<=INDEX(KHUNG_VAI_TRÒ!$E$9:$E$15,MATCH($C16,KHUNG_VAI_TRÒ!$A$9:$A$15,0))+0.0001,F16/KHUNG_VAI_TRÒ!$D$5>=INDEX(KHUNG_VAI_TRÒ!$F$9:$F$15,MATCH($C16,KHUNG_VAI_TRÒ!$A$9:$A$15,0))-0.0001,F16/KHUNG_VAI_TRÒ!$D$5<=INDEX(KHUNG_VAI_TRÒ!$G$9:$G$15,MATCH($C16,KHUNG_VAI_TRÒ!$A$9:$A$15,0))+0.0001,G16/KHUNG_VAI_TRÒ!$E$5>=INDEX(KHUNG_VAI_TRÒ!$H$9:$H$15,MATCH($C16,KHUNG_VAI_TRÒ!$A$9:$A$15,0))-0.0001,G16/KHUNG_VAI_TRÒ!$E$5<=INDEX(KHUNG_VAI_TRÒ!$I$9:$I$15,MATCH($C16,KHUNG_VAI_TRÒ!$A$9:$A$15,0))+0.0001),"OK","Ngoài khung"),"Vai trò?"))
A17: =NHÂN_VẬT!$A$17 -> NV13 | B17: =IF(NHÂN_VẬT!$B$17="","",NHÂN_VẬT!$B$17) | C17: =IF(NHÂN_VẬT!$D$17="","",NHÂN_VẬT!$D$17) | N17: =IF(OR(D17="",E17="",F17=""),"",D17*(100+F17)/100*E17/(KHUNG_VAI_TRÒ!$B$5*(100+KHUNG_VAI_TRÒ!$D$5)/100*KHUNG_VAI_TRÒ!$C$5)) | O17: =IF(OR(D17="",E17="",F17="",G17="",C17=""),"",IFERROR(IF(AND(D17/KHUNG_VAI_TRÒ!$B$5>=INDEX(KHUNG_VAI_TRÒ!$B$9:$B$15,MATCH($C17,KHUNG_VAI_TRÒ!$A$9:$A$15,0))-0.0001,D17/KHUNG_VAI_TRÒ!$B$5<=INDEX(KHUNG_VAI_TRÒ!$C$9:$C$15,MATCH($C17,KHUNG_VAI_TRÒ!$A$9:$A$15,0))+0.0001,E17/KHUNG_VAI_TRÒ!$C$5>=INDEX(KHUNG_VAI_TRÒ!$D$9:$D$15,MATCH($C17,KHUNG_VAI_TRÒ!$A$9:$A$15,0))-0.0001,E17/KHUNG_VAI_TRÒ!$C$5<=INDEX(KHUNG_VAI_TRÒ!$E$9:$E$15,MATCH($C17,KHUNG_VAI_TRÒ!$A$9:$A$15,0))+0.0001,F17/KHUNG_VAI_TRÒ!$D$5>=INDEX(KHUNG_VAI_TRÒ!$F$9:$F$15,MATCH($C17,KHUNG_VAI_TRÒ!$A$9:$A$15,0))-0.0001,F17/KHUNG_VAI_TRÒ!$D$5<=INDEX(KHUNG_VAI_TRÒ!$G$9:$G$15,MATCH($C17,KHUNG_VAI_TRÒ!$A$9:$A$15,0))+0.0001,G17/KHUNG_VAI_TRÒ!$E$5>=INDEX(KHUNG_VAI_TRÒ!$H$9:$H$15,MATCH($C17,KHUNG_VAI_TRÒ!$A$9:$A$15,0))-0.0001,G17/KHUNG_VAI_TRÒ!$E$5<=INDEX(KHUNG_VAI_TRÒ!$I$9:$I$15,MATCH($C17,KHUNG_VAI_TRÒ!$A$9:$A$15,0))+0.0001),"OK","Ngoài khung"),"Vai trò?"))
A18: =NHÂN_VẬT!$A$18 -> NV14 | B18: =IF(NHÂN_VẬT!$B$18="","",NHÂN_VẬT!$B$18) | C18: =IF(NHÂN_VẬT!$D$18="","",NHÂN_VẬT!$D$18) | N18: =IF(OR(D18="",E18="",F18=""),"",D18*(100+F18)/100*E18/(KHUNG_VAI_TRÒ!$B$5*(100+KHUNG_VAI_TRÒ!$D$5)/100*KHUNG_VAI_TRÒ!$C$5)) | O18: =IF(OR(D18="",E18="",F18="",G18="",C18=""),"",IFERROR(IF(AND(D18/KHUNG_VAI_TRÒ!$B$5>=INDEX(KHUNG_VAI_TRÒ!$B$9:$B$15,MATCH($C18,KHUNG_VAI_TRÒ!$A$9:$A$15,0))-0.0001,D18/KHUNG_VAI_TRÒ!$B$5<=INDEX(KHUNG_VAI_TRÒ!$C$9:$C$15,MATCH($C18,KHUNG_VAI_TRÒ!$A$9:$A$15,0))+0.0001,E18/KHUNG_VAI_TRÒ!$C$5>=INDEX(KHUNG_VAI_TRÒ!$D$9:$D$15,MATCH($C18,KHUNG_VAI_TRÒ!$A$9:$A$15,0))-0.0001,E18/KHUNG_VAI_TRÒ!$C$5<=INDEX(KHUNG_VAI_TRÒ!$E$9:$E$15,MATCH($C18,KHUNG_VAI_TRÒ!$A$9:$A$15,0))+0.0001,F18/KHUNG_VAI_TRÒ!$D$5>=INDEX(KHUNG_VAI_TRÒ!$F$9:$F$15,MATCH($C18,KHUNG_VAI_TRÒ!$A$9:$A$15,0))-0.0001,F18/KHUNG_VAI_TRÒ!$D$5<=INDEX(KHUNG_VAI_TRÒ!$G$9:$G$15,MATCH($C18,KHUNG_VAI_TRÒ!$A$9:$A$15,0))+0.0001,G18/KHUNG_VAI_TRÒ!$E$5>=INDEX(KHUNG_VAI_TRÒ!$H$9:$H$15,MATCH($C18,KHUNG_VAI_TRÒ!$A$9:$A$15,0))-0.0001,G18/KHUNG_VAI_TRÒ!$E$5<=INDEX(KHUNG_VAI_TRÒ!$I$9:$I$15,MATCH($C18,KHUNG_VAI_TRÒ!$A$9:$A$15,0))+0.0001),"OK","Ngoài khung"),"Vai trò?"))
A19: =NHÂN_VẬT!$A$19 -> NV15 | B19: =IF(NHÂN_VẬT!$B$19="","",NHÂN_VẬT!$B$19) | C19: =IF(NHÂN_VẬT!$D$19="","",NHÂN_VẬT!$D$19) | N19: =IF(OR(D19="",E19="",F19=""),"",D19*(100+F19)/100*E19/(KHUNG_VAI_TRÒ!$B$5*(100+KHUNG_VAI_TRÒ!$D$5)/100*KHUNG_VAI_TRÒ!$C$5)) | O19: =IF(OR(D19="",E19="",F19="",G19="",C19=""),"",IFERROR(IF(AND(D19/KHUNG_VAI_TRÒ!$B$5>=INDEX(KHUNG_VAI_TRÒ!$B$9:$B$15,MATCH($C19,KHUNG_VAI_TRÒ!$A$9:$A$15,0))-0.0001,D19/KHUNG_VAI_TRÒ!$B$5<=INDEX(KHUNG_VAI_TRÒ!$C$9:$C$15,MATCH($C19,KHUNG_VAI_TRÒ!$A$9:$A$15,0))+0.0001,E19/KHUNG_VAI_TRÒ!$C$5>=INDEX(KHUNG_VAI_TRÒ!$D$9:$D$15,MATCH($C19,KHUNG_VAI_TRÒ!$A$9:$A$15,0))-0.0001,E19/KHUNG_VAI_TRÒ!$C$5<=INDEX(KHUNG_VAI_TRÒ!$E$9:$E$15,MATCH($C19,KHUNG_VAI_TRÒ!$A$9:$A$15,0))+0.0001,F19/KHUNG_VAI_TRÒ!$D$5>=INDEX(KHUNG_VAI_TRÒ!$F$9:$F$15,MATCH($C19,KHUNG_VAI_TRÒ!$A$9:$A$15,0))-0.0001,F19/KHUNG_VAI_TRÒ!$D$5<=INDEX(KHUNG_VAI_TRÒ!$G$9:$G$15,MATCH($C19,KHUNG_VAI_TRÒ!$A$9:$A$15,0))+0.0001,G19/KHUNG_VAI_TRÒ!$E$5>=INDEX(KHUNG_VAI_TRÒ!$H$9:$H$15,MATCH($C19,KHUNG_VAI_TRÒ!$A$9:$A$15,0))-0.0001,G19/KHUNG_VAI_TRÒ!$E$5<=INDEX(KHUNG_VAI_TRÒ!$I$9:$I$15,MATCH($C19,KHUNG_VAI_TRÒ!$A$9:$A$15,0))+0.0001),"OK","Ngoài khung"),"Vai trò?"))
A20: =NHÂN_VẬT!$A$20 -> NV16 | B20: =IF(NHÂN_VẬT!$B$20="","",NHÂN_VẬT!$B$20) | C20: =IF(NHÂN_VẬT!$D$20="","",NHÂN_VẬT!$D$20) | N20: =IF(OR(D20="",E20="",F20=""),"",D20*(100+F20)/100*E20/(KHUNG_VAI_TRÒ!$B$5*(100+KHUNG_VAI_TRÒ!$D$5)/100*KHUNG_VAI_TRÒ!$C$5)) | O20: =IF(OR(D20="",E20="",F20="",G20="",C20=""),"",IFERROR(IF(AND(D20/KHUNG_VAI_TRÒ!$B$5>=INDEX(KHUNG_VAI_TRÒ!$B$9:$B$15,MATCH($C20,KHUNG_VAI_TRÒ!$A$9:$A$15,0))-0.0001,D20/KHUNG_VAI_TRÒ!$B$5<=INDEX(KHUNG_VAI_TRÒ!$C$9:$C$15,MATCH($C20,KHUNG_VAI_TRÒ!$A$9:$A$15,0))+0.0001,E20/KHUNG_VAI_TRÒ!$C$5>=INDEX(KHUNG_VAI_TRÒ!$D$9:$D$15,MATCH($C20,KHUNG_VAI_TRÒ!$A$9:$A$15,0))-0.0001,E20/KHUNG_VAI_TRÒ!$C$5<=INDEX(KHUNG_VAI_TRÒ!$E$9:$E$15,MATCH($C20,KHUNG_VAI_TRÒ!$A$9:$A$15,0))+0.0001,F20/KHUNG_VAI_TRÒ!$D$5>=INDEX(KHUNG_VAI_TRÒ!$F$9:$F$15,MATCH($C20,KHUNG_VAI_TRÒ!$A$9:$A$15,0))-0.0001,F20/KHUNG_VAI_TRÒ!$D$5<=INDEX(KHUNG_VAI_TRÒ!$G$9:$G$15,MATCH($C20,KHUNG_VAI_TRÒ!$A$9:$A$15,0))+0.0001,G20/KHUNG_VAI_TRÒ!$E$5>=INDEX(KHUNG_VAI_TRÒ!$H$9:$H$15,MATCH($C20,KHUNG_VAI_TRÒ!$A$9:$A$15,0))-0.0001,G20/KHUNG_VAI_TRÒ!$E$5<=INDEX(KHUNG_VAI_TRÒ!$I$9:$I$15,MATCH($C20,KHUNG_VAI_TRÒ!$A$9:$A$15,0))+0.0001),"OK","Ngoài khung"),"Vai trò?"))
A21: =NHÂN_VẬT!$A$21 -> NV17 | B21: =IF(NHÂN_VẬT!$B$21="","",NHÂN_VẬT!$B$21) | C21: =IF(NHÂN_VẬT!$D$21="","",NHÂN_VẬT!$D$21) | N21: =IF(OR(D21="",E21="",F21=""),"",D21*(100+F21)/100*E21/(KHUNG_VAI_TRÒ!$B$5*(100+KHUNG_VAI_TRÒ!$D$5)/100*KHUNG_VAI_TRÒ!$C$5)) | O21: =IF(OR(D21="",E21="",F21="",G21="",C21=""),"",IFERROR(IF(AND(D21/KHUNG_VAI_TRÒ!$B$5>=INDEX(KHUNG_VAI_TRÒ!$B$9:$B$15,MATCH($C21,KHUNG_VAI_TRÒ!$A$9:$A$15,0))-0.0001,D21/KHUNG_VAI_TRÒ!$B$5<=INDEX(KHUNG_VAI_TRÒ!$C$9:$C$15,MATCH($C21,KHUNG_VAI_TRÒ!$A$9:$A$15,0))+0.0001,E21/KHUNG_VAI_TRÒ!$C$5>=INDEX(KHUNG_VAI_TRÒ!$D$9:$D$15,MATCH($C21,KHUNG_VAI_TRÒ!$A$9:$A$15,0))-0.0001,E21/KHUNG_VAI_TRÒ!$C$5<=INDEX(KHUNG_VAI_TRÒ!$E$9:$E$15,MATCH($C21,KHUNG_VAI_TRÒ!$A$9:$A$15,0))+0.0001,F21/KHUNG_VAI_TRÒ!$D$5>=INDEX(KHUNG_VAI_TRÒ!$F$9:$F$15,MATCH($C21,KHUNG_VAI_TRÒ!$A$9:$A$15,0))-0.0001,F21/KHUNG_VAI_TRÒ!$D$5<=INDEX(KHUNG_VAI_TRÒ!$G$9:$G$15,MATCH($C21,KHUNG_VAI_TRÒ!$A$9:$A$15,0))+0.0001,G21/KHUNG_VAI_TRÒ!$E$5>=INDEX(KHUNG_VAI_TRÒ!$H$9:$H$15,MATCH($C21,KHUNG_VAI_TRÒ!$A$9:$A$15,0))-0.0001,G21/KHUNG_VAI_TRÒ!$E$5<=INDEX(KHUNG_VAI_TRÒ!$I$9:$I$15,MATCH($C21,KHUNG_VAI_TRÒ!$A$9:$A$15,0))+0.0001),"OK","Ngoài khung"),"Vai trò?"))
A22: =NHÂN_VẬT!$A$22 -> NV18 | B22: =IF(NHÂN_VẬT!$B$22="","",NHÂN_VẬT!$B$22) | C22: =IF(NHÂN_VẬT!$D$22="","",NHÂN_VẬT!$D$22) | N22: =IF(OR(D22="",E22="",F22=""),"",D22*(100+F22)/100*E22/(KHUNG_VAI_TRÒ!$B$5*(100+KHUNG_VAI_TRÒ!$D$5)/100*KHUNG_VAI_TRÒ!$C$5)) | O22: =IF(OR(D22="",E22="",F22="",G22="",C22=""),"",IFERROR(IF(AND(D22/KHUNG_VAI_TRÒ!$B$5>=INDEX(KHUNG_VAI_TRÒ!$B$9:$B$15,MATCH($C22,KHUNG_VAI_TRÒ!$A$9:$A$15,0))-0.0001,D22/KHUNG_VAI_TRÒ!$B$5<=INDEX(KHUNG_VAI_TRÒ!$C$9:$C$15,MATCH($C22,KHUNG_VAI_TRÒ!$A$9:$A$15,0))+0.0001,E22/KHUNG_VAI_TRÒ!$C$5>=INDEX(KHUNG_VAI_TRÒ!$D$9:$D$15,MATCH($C22,KHUNG_VAI_TRÒ!$A$9:$A$15,0))-0.0001,E22/KHUNG_VAI_TRÒ!$C$5<=INDEX(KHUNG_VAI_TRÒ!$E$9:$E$15,MATCH($C22,KHUNG_VAI_TRÒ!$A$9:$A$15,0))+0.0001,F22/KHUNG_VAI_TRÒ!$D$5>=INDEX(KHUNG_VAI_TRÒ!$F$9:$F$15,MATCH($C22,KHUNG_VAI_TRÒ!$A$9:$A$15,0))-0.0001,F22/KHUNG_VAI_TRÒ!$D$5<=INDEX(KHUNG_VAI_TRÒ!$G$9:$G$15,MATCH($C22,KHUNG_VAI_TRÒ!$A$9:$A$15,0))+0.0001,G22/KHUNG_VAI_TRÒ!$E$5>=INDEX(KHUNG_VAI_TRÒ!$H$9:$H$15,MATCH($C22,KHUNG_VAI_TRÒ!$A$9:$A$15,0))-0.0001,G22/KHUNG_VAI_TRÒ!$E$5<=INDEX(KHUNG_VAI_TRÒ!$I$9:$I$15,MATCH($C22,KHUNG_VAI_TRÒ!$A$9:$A$15,0))+0.0001),"OK","Ngoài khung"),"Vai trò?"))
A23: =NHÂN_VẬT!$A$23 -> NV19 | B23: =IF(NHÂN_VẬT!$B$23="","",NHÂN_VẬT!$B$23) | C23: =IF(NHÂN_VẬT!$D$23="","",NHÂN_VẬT!$D$23) | N23: =IF(OR(D23="",E23="",F23=""),"",D23*(100+F23)/100*E23/(KHUNG_VAI_TRÒ!$B$5*(100+KHUNG_VAI_TRÒ!$D$5)/100*KHUNG_VAI_TRÒ!$C$5)) | O23: =IF(OR(D23="",E23="",F23="",G23="",C23=""),"",IFERROR(IF(AND(D23/KHUNG_VAI_TRÒ!$B$5>=INDEX(KHUNG_VAI_TRÒ!$B$9:$B$15,MATCH($C23,KHUNG_VAI_TRÒ!$A$9:$A$15,0))-0.0001,D23/KHUNG_VAI_TRÒ!$B$5<=INDEX(KHUNG_VAI_TRÒ!$C$9:$C$15,MATCH($C23,KHUNG_VAI_TRÒ!$A$9:$A$15,0))+0.0001,E23/KHUNG_VAI_TRÒ!$C$5>=INDEX(KHUNG_VAI_TRÒ!$D$9:$D$15,MATCH($C23,KHUNG_VAI_TRÒ!$A$9:$A$15,0))-0.0001,E23/KHUNG_VAI_TRÒ!$C$5<=INDEX(KHUNG_VAI_TRÒ!$E$9:$E$15,MATCH($C23,KHUNG_VAI_TRÒ!$A$9:$A$15,0))+0.0001,F23/KHUNG_VAI_TRÒ!$D$5>=INDEX(KHUNG_VAI_TRÒ!$F$9:$F$15,MATCH($C23,KHUNG_VAI_TRÒ!$A$9:$A$15,0))-0.0001,F23/KHUNG_VAI_TRÒ!$D$5<=INDEX(KHUNG_VAI_TRÒ!$G$9:$G$15,MATCH($C23,KHUNG_VAI_TRÒ!$A$9:$A$15,0))+0.0001,G23/KHUNG_VAI_TRÒ!$E$5>=INDEX(KHUNG_VAI_TRÒ!$H$9:$H$15,MATCH($C23,KHUNG_VAI_TRÒ!$A$9:$A$15,0))-0.0001,G23/KHUNG_VAI_TRÒ!$E$5<=INDEX(KHUNG_VAI_TRÒ!$I$9:$I$15,MATCH($C23,KHUNG_VAI_TRÒ!$A$9:$A$15,0))+0.0001),"OK","Ngoài khung"),"Vai trò?"))
A24: =NHÂN_VẬT!$A$24 -> NV20 | B24: =IF(NHÂN_VẬT!$B$24="","",NHÂN_VẬT!$B$24) | C24: =IF(NHÂN_VẬT!$D$24="","",NHÂN_VẬT!$D$24) | N24: =IF(OR(D24="",E24="",F24=""),"",D24*(100+F24)/100*E24/(KHUNG_VAI_TRÒ!$B$5*(100+KHUNG_VAI_TRÒ!$D$5)/100*KHUNG_VAI_TRÒ!$C$5)) | O24: =IF(OR(D24="",E24="",F24="",G24="",C24=""),"",IFERROR(IF(AND(D24/KHUNG_VAI_TRÒ!$B$5>=INDEX(KHUNG_VAI_TRÒ!$B$9:$B$15,MATCH($C24,KHUNG_VAI_TRÒ!$A$9:$A$15,0))-0.0001,D24/KHUNG_VAI_TRÒ!$B$5<=INDEX(KHUNG_VAI_TRÒ!$C$9:$C$15,MATCH($C24,KHUNG_VAI_TRÒ!$A$9:$A$15,0))+0.0001,E24/KHUNG_VAI_TRÒ!$C$5>=INDEX(KHUNG_VAI_TRÒ!$D$9:$D$15,MATCH($C24,KHUNG_VAI_TRÒ!$A$9:$A$15,0))-0.0001,E24/KHUNG_VAI_TRÒ!$C$5<=INDEX(KHUNG_VAI_TRÒ!$E$9:$E$15,MATCH($C24,KHUNG_VAI_TRÒ!$A$9:$A$15,0))+0.0001,F24/KHUNG_VAI_TRÒ!$D$5>=INDEX(KHUNG_VAI_TRÒ!$F$9:$F$15,MATCH($C24,KHUNG_VAI_TRÒ!$A$9:$A$15,0))-0.0001,F24/KHUNG_VAI_TRÒ!$D$5<=INDEX(KHUNG_VAI_TRÒ!$G$9:$G$15,MATCH($C24,KHUNG_VAI_TRÒ!$A$9:$A$15,0))+0.0001,G24/KHUNG_VAI_TRÒ!$E$5>=INDEX(KHUNG_VAI_TRÒ!$H$9:$H$15,MATCH($C24,KHUNG_VAI_TRÒ!$A$9:$A$15,0))-0.0001,G24/KHUNG_VAI_TRÒ!$E$5<=INDEX(KHUNG_VAI_TRÒ!$I$9:$I$15,MATCH($C24,KHUNG_VAI_TRÒ!$A$9:$A$15,0))+0.0001),"OK","Ngoài khung"),"Vai trò?"))
A25: =NHÂN_VẬT!$A$25 -> NV21 | B25: =IF(NHÂN_VẬT!$B$25="","",NHÂN_VẬT!$B$25) | C25: =IF(NHÂN_VẬT!$D$25="","",NHÂN_VẬT!$D$25) | N25: =IF(OR(D25="",E25="",F25=""),"",D25*(100+F25)/100*E25/(KHUNG_VAI_TRÒ!$B$5*(100+KHUNG_VAI_TRÒ!$D$5)/100*KHUNG_VAI_TRÒ!$C$5)) | O25: =IF(OR(D25="",E25="",F25="",G25="",C25=""),"",IFERROR(IF(AND(D25/KHUNG_VAI_TRÒ!$B$5>=INDEX(KHUNG_VAI_TRÒ!$B$9:$B$15,MATCH($C25,KHUNG_VAI_TRÒ!$A$9:$A$15,0))-0.0001,D25/KHUNG_VAI_TRÒ!$B$5<=INDEX(KHUNG_VAI_TRÒ!$C$9:$C$15,MATCH($C25,KHUNG_VAI_TRÒ!$A$9:$A$15,0))+0.0001,E25/KHUNG_VAI_TRÒ!$C$5>=INDEX(KHUNG_VAI_TRÒ!$D$9:$D$15,MATCH($C25,KHUNG_VAI_TRÒ!$A$9:$A$15,0))-0.0001,E25/KHUNG_VAI_TRÒ!$C$5<=INDEX(KHUNG_VAI_TRÒ!$E$9:$E$15,MATCH($C25,KHUNG_VAI_TRÒ!$A$9:$A$15,0))+0.0001,F25/KHUNG_VAI_TRÒ!$D$5>=INDEX(KHUNG_VAI_TRÒ!$F$9:$F$15,MATCH($C25,KHUNG_VAI_TRÒ!$A$9:$A$15,0))-0.0001,F25/KHUNG_VAI_TRÒ!$D$5<=INDEX(KHUNG_VAI_TRÒ!$G$9:$G$15,MATCH($C25,KHUNG_VAI_TRÒ!$A$9:$A$15,0))+0.0001,G25/KHUNG_VAI_TRÒ!$E$5>=INDEX(KHUNG_VAI_TRÒ!$H$9:$H$15,MATCH($C25,KHUNG_VAI_TRÒ!$A$9:$A$15,0))-0.0001,G25/KHUNG_VAI_TRÒ!$E$5<=INDEX(KHUNG_VAI_TRÒ!$I$9:$I$15,MATCH($C25,KHUNG_VAI_TRÒ!$A$9:$A$15,0))+0.0001),"OK","Ngoài khung"),"Vai trò?"))
A26: =NHÂN_VẬT!$A$26 -> NV22 | B26: =IF(NHÂN_VẬT!$B$26="","",NHÂN_VẬT!$B$26) | C26: =IF(NHÂN_VẬT!$D$26="","",NHÂN_VẬT!$D$26) | N26: =IF(OR(D26="",E26="",F26=""),"",D26*(100+F26)/100*E26/(KHUNG_VAI_TRÒ!$B$5*(100+KHUNG_VAI_TRÒ!$D$5)/100*KHUNG_VAI_TRÒ!$C$5)) | O26: =IF(OR(D26="",E26="",F26="",G26="",C26=""),"",IFERROR(IF(AND(D26/KHUNG_VAI_TRÒ!$B$5>=INDEX(KHUNG_VAI_TRÒ!$B$9:$B$15,MATCH($C26,KHUNG_VAI_TRÒ!$A$9:$A$15,0))-0.0001,D26/KHUNG_VAI_TRÒ!$B$5<=INDEX(KHUNG_VAI_TRÒ!$C$9:$C$15,MATCH($C26,KHUNG_VAI_TRÒ!$A$9:$A$15,0))+0.0001,E26/KHUNG_VAI_TRÒ!$C$5>=INDEX(KHUNG_VAI_TRÒ!$D$9:$D$15,MATCH($C26,KHUNG_VAI_TRÒ!$A$9:$A$15,0))-0.0001,E26/KHUNG_VAI_TRÒ!$C$5<=INDEX(KHUNG_VAI_TRÒ!$E$9:$E$15,MATCH($C26,KHUNG_VAI_TRÒ!$A$9:$A$15,0))+0.0001,F26/KHUNG_VAI_TRÒ!$D$5>=INDEX(KHUNG_VAI_TRÒ!$F$9:$F$15,MATCH($C26,KHUNG_VAI_TRÒ!$A$9:$A$15,0))-0.0001,F26/KHUNG_VAI_TRÒ!$D$5<=INDEX(KHUNG_VAI_TRÒ!$G$9:$G$15,MATCH($C26,KHUNG_VAI_TRÒ!$A$9:$A$15,0))+0.0001,G26/KHUNG_VAI_TRÒ!$E$5>=INDEX(KHUNG_VAI_TRÒ!$H$9:$H$15,MATCH($C26,KHUNG_VAI_TRÒ!$A$9:$A$15,0))-0.0001,G26/KHUNG_VAI_TRÒ!$E$5<=INDEX(KHUNG_VAI_TRÒ!$I$9:$I$15,MATCH($C26,KHUNG_VAI_TRÒ!$A$9:$A$15,0))+0.0001),"OK","Ngoài khung"),"Vai trò?"))
A27: =NHÂN_VẬT!$A$27 -> NV23 | B27: =IF(NHÂN_VẬT!$B$27="","",NHÂN_VẬT!$B$27) | C27: =IF(NHÂN_VẬT!$D$27="","",NHÂN_VẬT!$D$27) | N27: =IF(OR(D27="",E27="",F27=""),"",D27*(100+F27)/100*E27/(KHUNG_VAI_TRÒ!$B$5*(100+KHUNG_VAI_TRÒ!$D$5)/100*KHUNG_VAI_TRÒ!$C$5)) | O27: =IF(OR(D27="",E27="",F27="",G27="",C27=""),"",IFERROR(IF(AND(D27/KHUNG_VAI_TRÒ!$B$5>=INDEX(KHUNG_VAI_TRÒ!$B$9:$B$15,MATCH($C27,KHUNG_VAI_TRÒ!$A$9:$A$15,0))-0.0001,D27/KHUNG_VAI_TRÒ!$B$5<=INDEX(KHUNG_VAI_TRÒ!$C$9:$C$15,MATCH($C27,KHUNG_VAI_TRÒ!$A$9:$A$15,0))+0.0001,E27/KHUNG_VAI_TRÒ!$C$5>=INDEX(KHUNG_VAI_TRÒ!$D$9:$D$15,MATCH($C27,KHUNG_VAI_TRÒ!$A$9:$A$15,0))-0.0001,E27/KHUNG_VAI_TRÒ!$C$5<=INDEX(KHUNG_VAI_TRÒ!$E$9:$E$15,MATCH($C27,KHUNG_VAI_TRÒ!$A$9:$A$15,0))+0.0001,F27/KHUNG_VAI_TRÒ!$D$5>=INDEX(KHUNG_VAI_TRÒ!$F$9:$F$15,MATCH($C27,KHUNG_VAI_TRÒ!$A$9:$A$15,0))-0.0001,F27/KHUNG_VAI_TRÒ!$D$5<=INDEX(KHUNG_VAI_TRÒ!$G$9:$G$15,MATCH($C27,KHUNG_VAI_TRÒ!$A$9:$A$15,0))+0.0001,G27/KHUNG_VAI_TRÒ!$E$5>=INDEX(KHUNG_VAI_TRÒ!$H$9:$H$15,MATCH($C27,KHUNG_VAI_TRÒ!$A$9:$A$15,0))-0.0001,G27/KHUNG_VAI_TRÒ!$E$5<=INDEX(KHUNG_VAI_TRÒ!$I$9:$I$15,MATCH($C27,KHUNG_VAI_TRÒ!$A$9:$A$15,0))+0.0001),"OK","Ngoài khung"),"Vai trò?"))
A28: =NHÂN_VẬT!$A$28 -> NV24 | B28: =IF(NHÂN_VẬT!$B$28="","",NHÂN_VẬT!$B$28) | C28: =IF(NHÂN_VẬT!$D$28="","",NHÂN_VẬT!$D$28) | N28: =IF(OR(D28="",E28="",F28=""),"",D28*(100+F28)/100*E28/(KHUNG_VAI_TRÒ!$B$5*(100+KHUNG_VAI_TRÒ!$D$5)/100*KHUNG_VAI_TRÒ!$C$5)) | O28: =IF(OR(D28="",E28="",F28="",G28="",C28=""),"",IFERROR(IF(AND(D28/KHUNG_VAI_TRÒ!$B$5>=INDEX(KHUNG_VAI_TRÒ!$B$9:$B$15,MATCH($C28,KHUNG_VAI_TRÒ!$A$9:$A$15,0))-0.0001,D28/KHUNG_VAI_TRÒ!$B$5<=INDEX(KHUNG_VAI_TRÒ!$C$9:$C$15,MATCH($C28,KHUNG_VAI_TRÒ!$A$9:$A$15,0))+0.0001,E28/KHUNG_VAI_TRÒ!$C$5>=INDEX(KHUNG_VAI_TRÒ!$D$9:$D$15,MATCH($C28,KHUNG_VAI_TRÒ!$A$9:$A$15,0))-0.0001,E28/KHUNG_VAI_TRÒ!$C$5<=INDEX(KHUNG_VAI_TRÒ!$E$9:$E$15,MATCH($C28,KHUNG_VAI_TRÒ!$A$9:$A$15,0))+0.0001,F28/KHUNG_VAI_TRÒ!$D$5>=INDEX(KHUNG_VAI_TRÒ!$F$9:$F$15,MATCH($C28,KHUNG_VAI_TRÒ!$A$9:$A$15,0))-0.0001,F28/KHUNG_VAI_TRÒ!$D$5<=INDEX(KHUNG_VAI_TRÒ!$G$9:$G$15,MATCH($C28,KHUNG_VAI_TRÒ!$A$9:$A$15,0))+0.0001,G28/KHUNG_VAI_TRÒ!$E$5>=INDEX(KHUNG_VAI_TRÒ!$H$9:$H$15,MATCH($C28,KHUNG_VAI_TRÒ!$A$9:$A$15,0))-0.0001,G28/KHUNG_VAI_TRÒ!$E$5<=INDEX(KHUNG_VAI_TRÒ!$I$9:$I$15,MATCH($C28,KHUNG_VAI_TRÒ!$A$9:$A$15,0))+0.0001),"OK","Ngoài khung"),"Vai trò?"))
A29: =NHÂN_VẬT!$A$29 -> NV25 | B29: =IF(NHÂN_VẬT!$B$29="","",NHÂN_VẬT!$B$29) | C29: =IF(NHÂN_VẬT!$D$29="","",NHÂN_VẬT!$D$29) | N29: =IF(OR(D29="",E29="",F29=""),"",D29*(100+F29)/100*E29/(KHUNG_VAI_TRÒ!$B$5*(100+KHUNG_VAI_TRÒ!$D$5)/100*KHUNG_VAI_TRÒ!$C$5)) | O29: =IF(OR(D29="",E29="",F29="",G29="",C29=""),"",IFERROR(IF(AND(D29/KHUNG_VAI_TRÒ!$B$5>=INDEX(KHUNG_VAI_TRÒ!$B$9:$B$15,MATCH($C29,KHUNG_VAI_TRÒ!$A$9:$A$15,0))-0.0001,D29/KHUNG_VAI_TRÒ!$B$5<=INDEX(KHUNG_VAI_TRÒ!$C$9:$C$15,MATCH($C29,KHUNG_VAI_TRÒ!$A$9:$A$15,0))+0.0001,E29/KHUNG_VAI_TRÒ!$C$5>=INDEX(KHUNG_VAI_TRÒ!$D$9:$D$15,MATCH($C29,KHUNG_VAI_TRÒ!$A$9:$A$15,0))-0.0001,E29/KHUNG_VAI_TRÒ!$C$5<=INDEX(KHUNG_VAI_TRÒ!$E$9:$E$15,MATCH($C29,KHUNG_VAI_TRÒ!$A$9:$A$15,0))+0.0001,F29/KHUNG_VAI_TRÒ!$D$5>=INDEX(KHUNG_VAI_TRÒ!$F$9:$F$15,MATCH($C29,KHUNG_VAI_TRÒ!$A$9:$A$15,0))-0.0001,F29/KHUNG_VAI_TRÒ!$D$5<=INDEX(KHUNG_VAI_TRÒ!$G$9:$G$15,MATCH($C29,KHUNG_VAI_TRÒ!$A$9:$A$15,0))+0.0001,G29/KHUNG_VAI_TRÒ!$E$5>=INDEX(KHUNG_VAI_TRÒ!$H$9:$H$15,MATCH($C29,KHUNG_VAI_TRÒ!$A$9:$A$15,0))-0.0001,G29/KHUNG_VAI_TRÒ!$E$5<=INDEX(KHUNG_VAI_TRÒ!$I$9:$I$15,MATCH($C29,KHUNG_VAI_TRÒ!$A$9:$A$15,0))+0.0001),"OK","Ngoài khung"),"Vai trò?"))
A30: =NHÂN_VẬT!$A$30 -> NV26 | B30: =IF(NHÂN_VẬT!$B$30="","",NHÂN_VẬT!$B$30) | C30: =IF(NHÂN_VẬT!$D$30="","",NHÂN_VẬT!$D$30) | N30: =IF(OR(D30="",E30="",F30=""),"",D30*(100+F30)/100*E30/(KHUNG_VAI_TRÒ!$B$5*(100+KHUNG_VAI_TRÒ!$D$5)/100*KHUNG_VAI_TRÒ!$C$5)) | O30: =IF(OR(D30="",E30="",F30="",G30="",C30=""),"",IFERROR(IF(AND(D30/KHUNG_VAI_TRÒ!$B$5>=INDEX(KHUNG_VAI_TRÒ!$B$9:$B$15,MATCH($C30,KHUNG_VAI_TRÒ!$A$9:$A$15,0))-0.0001,D30/KHUNG_VAI_TRÒ!$B$5<=INDEX(KHUNG_VAI_TRÒ!$C$9:$C$15,MATCH($C30,KHUNG_VAI_TRÒ!$A$9:$A$15,0))+0.0001,E30/KHUNG_VAI_TRÒ!$C$5>=INDEX(KHUNG_VAI_TRÒ!$D$9:$D$15,MATCH($C30,KHUNG_VAI_TRÒ!$A$9:$A$15,0))-0.0001,E30/KHUNG_VAI_TRÒ!$C$5<=INDEX(KHUNG_VAI_TRÒ!$E$9:$E$15,MATCH($C30,KHUNG_VAI_TRÒ!$A$9:$A$15,0))+0.0001,F30/KHUNG_VAI_TRÒ!$D$5>=INDEX(KHUNG_VAI_TRÒ!$F$9:$F$15,MATCH($C30,KHUNG_VAI_TRÒ!$A$9:$A$15,0))-0.0001,F30/KHUNG_VAI_TRÒ!$D$5<=INDEX(KHUNG_VAI_TRÒ!$G$9:$G$15,MATCH($C30,KHUNG_VAI_TRÒ!$A$9:$A$15,0))+0.0001,G30/KHUNG_VAI_TRÒ!$E$5>=INDEX(KHUNG_VAI_TRÒ!$H$9:$H$15,MATCH($C30,KHUNG_VAI_TRÒ!$A$9:$A$15,0))-0.0001,G30/KHUNG_VAI_TRÒ!$E$5<=INDEX(KHUNG_VAI_TRÒ!$I$9:$I$15,MATCH($C30,KHUNG_VAI_TRÒ!$A$9:$A$15,0))+0.0001),"OK","Ngoài khung"),"Vai trò?"))
A31: =NHÂN_VẬT!$A$31 -> NV27 | B31: =IF(NHÂN_VẬT!$B$31="","",NHÂN_VẬT!$B$31) | C31: =IF(NHÂN_VẬT!$D$31="","",NHÂN_VẬT!$D$31) | N31: =IF(OR(D31="",E31="",F31=""),"",D31*(100+F31)/100*E31/(KHUNG_VAI_TRÒ!$B$5*(100+KHUNG_VAI_TRÒ!$D$5)/100*KHUNG_VAI_TRÒ!$C$5)) | O31: =IF(OR(D31="",E31="",F31="",G31="",C31=""),"",IFERROR(IF(AND(D31/KHUNG_VAI_TRÒ!$B$5>=INDEX(KHUNG_VAI_TRÒ!$B$9:$B$15,MATCH($C31,KHUNG_VAI_TRÒ!$A$9:$A$15,0))-0.0001,D31/KHUNG_VAI_TRÒ!$B$5<=INDEX(KHUNG_VAI_TRÒ!$C$9:$C$15,MATCH($C31,KHUNG_VAI_TRÒ!$A$9:$A$15,0))+0.0001,E31/KHUNG_VAI_TRÒ!$C$5>=INDEX(KHUNG_VAI_TRÒ!$D$9:$D$15,MATCH($C31,KHUNG_VAI_TRÒ!$A$9:$A$15,0))-0.0001,E31/KHUNG_VAI_TRÒ!$C$5<=INDEX(KHUNG_VAI_TRÒ!$E$9:$E$15,MATCH($C31,KHUNG_VAI_TRÒ!$A$9:$A$15,0))+0.0001,F31/KHUNG_VAI_TRÒ!$D$5>=INDEX(KHUNG_VAI_TRÒ!$F$9:$F$15,MATCH($C31,KHUNG_VAI_TRÒ!$A$9:$A$15,0))-0.0001,F31/KHUNG_VAI_TRÒ!$D$5<=INDEX(KHUNG_VAI_TRÒ!$G$9:$G$15,MATCH($C31,KHUNG_VAI_TRÒ!$A$9:$A$15,0))+0.0001,G31/KHUNG_VAI_TRÒ!$E$5>=INDEX(KHUNG_VAI_TRÒ!$H$9:$H$15,MATCH($C31,KHUNG_VAI_TRÒ!$A$9:$A$15,0))-0.0001,G31/KHUNG_VAI_TRÒ!$E$5<=INDEX(KHUNG_VAI_TRÒ!$I$9:$I$15,MATCH($C31,KHUNG_VAI_TRÒ!$A$9:$A$15,0))+0.0001),"OK","Ngoài khung"),"Vai trò?"))
A32: =NHÂN_VẬT!$A$32 -> NV28 | B32: =IF(NHÂN_VẬT!$B$32="","",NHÂN_VẬT!$B$32) | C32: =IF(NHÂN_VẬT!$D$32="","",NHÂN_VẬT!$D$32) | N32: =IF(OR(D32="",E32="",F32=""),"",D32*(100+F32)/100*E32/(KHUNG_VAI_TRÒ!$B$5*(100+KHUNG_VAI_TRÒ!$D$5)/100*KHUNG_VAI_TRÒ!$C$5)) | O32: =IF(OR(D32="",E32="",F32="",G32="",C32=""),"",IFERROR(IF(AND(D32/KHUNG_VAI_TRÒ!$B$5>=INDEX(KHUNG_VAI_TRÒ!$B$9:$B$15,MATCH($C32,KHUNG_VAI_TRÒ!$A$9:$A$15,0))-0.0001,D32/KHUNG_VAI_TRÒ!$B$5<=INDEX(KHUNG_VAI_TRÒ!$C$9:$C$15,MATCH($C32,KHUNG_VAI_TRÒ!$A$9:$A$15,0))+0.0001,E32/KHUNG_VAI_TRÒ!$C$5>=INDEX(KHUNG_VAI_TRÒ!$D$9:$D$15,MATCH($C32,KHUNG_VAI_TRÒ!$A$9:$A$15,0))-0.0001,E32/KHUNG_VAI_TRÒ!$C$5<=INDEX(KHUNG_VAI_TRÒ!$E$9:$E$15,MATCH($C32,KHUNG_VAI_TRÒ!$A$9:$A$15,0))+0.0001,F32/KHUNG_VAI_TRÒ!$D$5>=INDEX(KHUNG_VAI_TRÒ!$F$9:$F$15,MATCH($C32,KHUNG_VAI_TRÒ!$A$9:$A$15,0))-0.0001,F32/KHUNG_VAI_TRÒ!$D$5<=INDEX(KHUNG_VAI_TRÒ!$G$9:$G$15,MATCH($C32,KHUNG_VAI_TRÒ!$A$9:$A$15,0))+0.0001,G32/KHUNG_VAI_TRÒ!$E$5>=INDEX(KHUNG_VAI_TRÒ!$H$9:$H$15,MATCH($C32,KHUNG_VAI_TRÒ!$A$9:$A$15,0))-0.0001,G32/KHUNG_VAI_TRÒ!$E$5<=INDEX(KHUNG_VAI_TRÒ!$I$9:$I$15,MATCH($C32,KHUNG_VAI_TRÒ!$A$9:$A$15,0))+0.0001),"OK","Ngoài khung"),"Vai trò?"))
A33: =NHÂN_VẬT!$A$33 -> NV29 | B33: =IF(NHÂN_VẬT!$B$33="","",NHÂN_VẬT!$B$33) | C33: =IF(NHÂN_VẬT!$D$33="","",NHÂN_VẬT!$D$33) | N33: =IF(OR(D33="",E33="",F33=""),"",D33*(100+F33)/100*E33/(KHUNG_VAI_TRÒ!$B$5*(100+KHUNG_VAI_TRÒ!$D$5)/100*KHUNG_VAI_TRÒ!$C$5)) | O33: =IF(OR(D33="",E33="",F33="",G33="",C33=""),"",IFERROR(IF(AND(D33/KHUNG_VAI_TRÒ!$B$5>=INDEX(KHUNG_VAI_TRÒ!$B$9:$B$15,MATCH($C33,KHUNG_VAI_TRÒ!$A$9:$A$15,0))-0.0001,D33/KHUNG_VAI_TRÒ!$B$5<=INDEX(KHUNG_VAI_TRÒ!$C$9:$C$15,MATCH($C33,KHUNG_VAI_TRÒ!$A$9:$A$15,0))+0.0001,E33/KHUNG_VAI_TRÒ!$C$5>=INDEX(KHUNG_VAI_TRÒ!$D$9:$D$15,MATCH($C33,KHUNG_VAI_TRÒ!$A$9:$A$15,0))-0.0001,E33/KHUNG_VAI_TRÒ!$C$5<=INDEX(KHUNG_VAI_TRÒ!$E$9:$E$15,MATCH($C33,KHUNG_VAI_TRÒ!$A$9:$A$15,0))+0.0001,F33/KHUNG_VAI_TRÒ!$D$5>=INDEX(KHUNG_VAI_TRÒ!$F$9:$F$15,MATCH($C33,KHUNG_VAI_TRÒ!$A$9:$A$15,0))-0.0001,F33/KHUNG_VAI_TRÒ!$D$5<=INDEX(KHUNG_VAI_TRÒ!$G$9:$G$15,MATCH($C33,KHUNG_VAI_TRÒ!$A$9:$A$15,0))+0.0001,G33/KHUNG_VAI_TRÒ!$E$5>=INDEX(KHUNG_VAI_TRÒ!$H$9:$H$15,MATCH($C33,KHUNG_VAI_TRÒ!$A$9:$A$15,0))-0.0001,G33/KHUNG_VAI_TRÒ!$E$5<=INDEX(KHUNG_VAI_TRÒ!$I$9:$I$15,MATCH($C33,KHUNG_VAI_TRÒ!$A$9:$A$15,0))+0.0001),"OK","Ngoài khung"),"Vai trò?"))
A34: =NHÂN_VẬT!$A$34 -> NV30 | B34: =IF(NHÂN_VẬT!$B$34="","",NHÂN_VẬT!$B$34) | C34: =IF(NHÂN_VẬT!$D$34="","",NHÂN_VẬT!$D$34) | N34: =IF(OR(D34="",E34="",F34=""),"",D34*(100+F34)/100*E34/(KHUNG_VAI_TRÒ!$B$5*(100+KHUNG_VAI_TRÒ!$D$5)/100*KHUNG_VAI_TRÒ!$C$5)) | O34: =IF(OR(D34="",E34="",F34="",G34="",C34=""),"",IFERROR(IF(AND(D34/KHUNG_VAI_TRÒ!$B$5>=INDEX(KHUNG_VAI_TRÒ!$B$9:$B$15,MATCH($C34,KHUNG_VAI_TRÒ!$A$9:$A$15,0))-0.0001,D34/KHUNG_VAI_TRÒ!$B$5<=INDEX(KHUNG_VAI_TRÒ!$C$9:$C$15,MATCH($C34,KHUNG_VAI_TRÒ!$A$9:$A$15,0))+0.0001,E34/KHUNG_VAI_TRÒ!$C$5>=INDEX(KHUNG_VAI_TRÒ!$D$9:$D$15,MATCH($C34,KHUNG_VAI_TRÒ!$A$9:$A$15,0))-0.0001,E34/KHUNG_VAI_TRÒ!$C$5<=INDEX(KHUNG_VAI_TRÒ!$E$9:$E$15,MATCH($C34,KHUNG_VAI_TRÒ!$A$9:$A$15,0))+0.0001,F34/KHUNG_VAI_TRÒ!$D$5>=INDEX(KHUNG_VAI_TRÒ!$F$9:$F$15,MATCH($C34,KHUNG_VAI_TRÒ!$A$9:$A$15,0))-0.0001,F34/KHUNG_VAI_TRÒ!$D$5<=INDEX(KHUNG_VAI_TRÒ!$G$9:$G$15,MATCH($C34,KHUNG_VAI_TRÒ!$A$9:$A$15,0))+0.0001,G34/KHUNG_VAI_TRÒ!$E$5>=INDEX(KHUNG_VAI_TRÒ!$H$9:$H$15,MATCH($C34,KHUNG_VAI_TRÒ!$A$9:$A$15,0))-0.0001,G34/KHUNG_VAI_TRÒ!$E$5<=INDEX(KHUNG_VAI_TRÒ!$I$9:$I$15,MATCH($C34,KHUNG_VAI_TRÒ!$A$9:$A$15,0))+0.0001),"OK","Ngoài khung"),"Vai trò?"))

Sheet HỆ_SỐ_PHẨM_CHẤT
A1: HỆ SỐ THEO PHẨM CHẤT (SỐ GIẢ do Claude đặt tạm)
A2: Bản demo chỉ dùng 3 dòng đầu (Trắng, Xanh lá, Xanh dương). Tím và Đỏ để sau.
A4: Phẩm chất | B4: Màu hiển thị | C4: Hệ số Máu (×) | D4: Hệ số Công (×) | E4: Hệ số Thủ (×) | F4: Hệ số Hồi máu (×) | G4: Cộng Tốc độ (điểm) | H4: Cộng Né (điểm %) | I4: Cộng Chính xác (điểm %) | J4: Cộng Tỷ lệ chí mạng (điểm %) | K4: Cộng Sát thương chí mạng (điểm %) | L4: Cộng Kháng chí mạng (điểm %) | M4: Ghi chú
A5: Trắng | B5: Trắng | C5: 1 | D5: 1 | E5: 1 | F5: 1 | G5: 0 | H5: 0 | I5: 0 | J5: 0 | K5: 0 | L5: 0 | M5: số giả
A6: Xanh lá | B6: Xanh lá | C6: 1.15 | D6: 1.15 | E6: 1.15 | F6: 1.15 | G6: 1 | H6: 0.005 | I6: 0.005 | J6: 0.005 | K6: 0 | L6: 0.005 | M6: số giả
A7: Xanh dương | B7: Xanh dương | C7: 1.3 | D7: 1.3 | E7: 1.3 | F7: 1.3 | G7: 2 | H7: 0.01 | I7: 0.01 | J7: 0.01 | K7: 0.05 | L7: 0.01 | M7: số giả
A8: Tím | B8: Tím | C8: 1.5 | D8: 1.5 | E8: 1.5 | F8: 1.5 | G8: 3 | H8: 0.015 | I8: 0.015 | J8: 0.015 | K8: 0.1 | L8: 0.015 | M8: số giả (chưa dùng ở demo)
A9: Đỏ | B9: Đỏ | C9: 1.75 | D9: 1.75 | E9: 1.75 | F9: 1.75 | G9: 4 | H9: 0.02 | I9: 0.02 | J9: 0.02 | K9: 0.15 | L9: 0.02 | M9: số giả (chưa dùng ở demo)
A11: Máu, Công, Thủ, Hồi máu = chỉ số Trắng × hệ số. Các chỉ số còn lại = chỉ số Trắng + điểm cộng.
A12: Tốc độ cộng nhỏ để 8 tướng demo không trùng tốc độ giữa các phẩm chất (gacha ẩn chỉ chạy khi trùng chính xác).

Sheet CHỈ_SỐ_TÍNH
A1: CHỈ SỐ TỪNG PHẨM CHẤT (TỰ TÍNH)
A2: Ô xanh nhạt là công thức. Muốn chỉnh tay một ô thì gõ đè. Demo dùng 3 dòng đầu mỗi tướng (Trắng, Xanh lá, Xanh dương).
A4: Mã NV | B4: Tên nhân vật | C4: Phẩm chất | D4: Máu | E4: Công | F4: Thủ | G4: Tốc độ | H4: Hồi máu / lượt | I4: Né (%) | J4: Chính xác (%) | K4: Tỷ lệ chí mạng (%) | L4: Sát thương chí mạng (%) | M4: Kháng chí mạng (%) | N4: Cảnh báo
A5: =NHÂN_VẬT!$A$6 -> NV01 | B5: =IF(NHÂN_VẬT!$B$6="","",NHÂN_VẬT!$B$6) -> HCM-THỦ KHO HIẾU | C5: =HỆ_SỐ_PHẨM_CHẤT!$A$5 -> Trắng | D5: =IF(CHỈ_SỐ_TRẮNG!$D$6="","",ROUND(CHỈ_SỐ_TRẮNG!$D$6*HỆ_SỐ_PHẨM_CHẤT!$C$5,0)) -> 1500 | E5: =IF(CHỈ_SỐ_TRẮNG!$E$6="","",ROUND(CHỈ_SỐ_TRẮNG!$E$6*HỆ_SỐ_PHẨM_CHẤT!$D$5,0)) -> 65 | F5: =IF(CHỈ_SỐ_TRẮNG!$F$6="","",ROUND(CHỈ_SỐ_TRẮNG!$F$6*HỆ_SỐ_PHẨM_CHẤT!$E$5,0)) -> 64 | G5: =IF(CHỈ_SỐ_TRẮNG!$G$6="","",CHỈ_SỐ_TRẮNG!$G$6+HỆ_SỐ_PHẨM_CHẤT!$G$5) -> 88 | H5: =IF(CHỈ_SỐ_TRẮNG!$H$6="","",ROUND(CHỈ_SỐ_TRẮNG!$H$6*HỆ_SỐ_PHẨM_CHẤT!$F$5,1)) -> 24 | I5: =IF(CHỈ_SỐ_TRẮNG!$I$6="","",CHỈ_SỐ_TRẮNG!$I$6+HỆ_SỐ_PHẨM_CHẤT!$H$5) -> 0.02 | J5: =IF(CHỈ_SỐ_TRẮNG!$J$6="","",CHỈ_SỐ_TRẮNG!$J$6+HỆ_SỐ_PHẨM_CHẤT!$I$5) -> 0.02 | K5: =IF(CHỈ_SỐ_TRẮNG!$K$6="","",CHỈ_SỐ_TRẮNG!$K$6+HỆ_SỐ_PHẨM_CHẤT!$J$5) -> 0.03 | L5: =IF(CHỈ_SỐ_TRẮNG!$L$6="","",CHỈ_SỐ_TRẮNG!$L$6+HỆ_SỐ_PHẨM_CHẤT!$K$5) -> 1.5 | M5: =IF(CHỈ_SỐ_TRẮNG!$M$6="","",CHỈ_SỐ_TRẮNG!$M$6+HỆ_SỐ_PHẨM_CHẤT!$L$5) -> 0.06 | N5: =IF(OR(N(I5)>0.1,N(K5)>0.1),"Né/chí mạng vượt 10%","")
A6: =NHÂN_VẬT!$A$6 -> NV01 | B6: =IF(NHÂN_VẬT!$B$6="","",NHÂN_VẬT!$B$6) -> HCM-THỦ KHO HIẾU | C6: =HỆ_SỐ_PHẨM_CHẤT!$A$6 -> Xanh lá | D6: =IF(CHỈ_SỐ_TRẮNG!$D$6="","",ROUND(CHỈ_SỐ_TRẮNG!$D$6*HỆ_SỐ_PHẨM_CHẤT!$C$6,0)) -> 1725 | E6: =IF(CHỈ_SỐ_TRẮNG!$E$6="","",ROUND(CHỈ_SỐ_TRẮNG!$E$6*HỆ_SỐ_PHẨM_CHẤT!$D$6,0)) -> 75 | F6: =IF(CHỈ_SỐ_TRẮNG!$F$6="","",ROUND(CHỈ_SỐ_TRẮNG!$F$6*HỆ_SỐ_PHẨM_CHẤT!$E$6,0)) -> 74 | G6: =IF(CHỈ_SỐ_TRẮNG!$G$6="","",CHỈ_SỐ_TRẮNG!$G$6+HỆ_SỐ_PHẨM_CHẤT!$G$6) -> 89 | H6: =IF(CHỈ_SỐ_TRẮNG!$H$6="","",ROUND(CHỈ_SỐ_TRẮNG!$H$6*HỆ_SỐ_PHẨM_CHẤT!$F$6,1)) -> 27.6 | I6: =IF(CHỈ_SỐ_TRẮNG!$I$6="","",CHỈ_SỐ_TRẮNG!$I$6+HỆ_SỐ_PHẨM_CHẤT!$H$6) -> 0.025 | J6: =IF(CHỈ_SỐ_TRẮNG!$J$6="","",CHỈ_SỐ_TRẮNG!$J$6+HỆ_SỐ_PHẨM_CHẤT!$I$6) -> 0.025 | K6: =IF(CHỈ_SỐ_TRẮNG!$K$6="","",CHỈ_SỐ_TRẮNG!$K$6+HỆ_SỐ_PHẨM_CHẤT!$J$6) -> 0.035 | L6: =IF(CHỈ_SỐ_TRẮNG!$L$6="","",CHỈ_SỐ_TRẮNG!$L$6+HỆ_SỐ_PHẨM_CHẤT!$K$6) -> 1.5 | M6: =IF(CHỈ_SỐ_TRẮNG!$M$6="","",CHỈ_SỐ_TRẮNG!$M$6+HỆ_SỐ_PHẨM_CHẤT!$L$6) -> 0.065 | N6: =IF(OR(N(I6)>0.1,N(K6)>0.1),"Né/chí mạng vượt 10%","")
A7: =NHÂN_VẬT!$A$6 -> NV01 | B7: =IF(NHÂN_VẬT!$B$6="","",NHÂN_VẬT!$B$6) -> HCM-THỦ KHO HIẾU | C7: =HỆ_SỐ_PHẨM_CHẤT!$A$7 -> Xanh dương | D7: =IF(CHỈ_SỐ_TRẮNG!$D$6="","",ROUND(CHỈ_SỐ_TRẮNG!$D$6*HỆ_SỐ_PHẨM_CHẤT!$C$7,0)) -> 1950 | E7: =IF(CHỈ_SỐ_TRẮNG!$E$6="","",ROUND(CHỈ_SỐ_TRẮNG!$E$6*HỆ_SỐ_PHẨM_CHẤT!$D$7,0)) -> 85 | F7: =IF(CHỈ_SỐ_TRẮNG!$F$6="","",ROUND(CHỈ_SỐ_TRẮNG!$F$6*HỆ_SỐ_PHẨM_CHẤT!$E$7,0)) -> 83 | G7: =IF(CHỈ_SỐ_TRẮNG!$G$6="","",CHỈ_SỐ_TRẮNG!$G$6+HỆ_SỐ_PHẨM_CHẤT!$G$7) -> 90 | H7: =IF(CHỈ_SỐ_TRẮNG!$H$6="","",ROUND(CHỈ_SỐ_TRẮNG!$H$6*HỆ_SỐ_PHẨM_CHẤT!$F$7,1)) -> 31.2 | I7: =IF(CHỈ_SỐ_TRẮNG!$I$6="","",CHỈ_SỐ_TRẮNG!$I$6+HỆ_SỐ_PHẨM_CHẤT!$H$7) -> 0.03 | J7: =IF(CHỈ_SỐ_TRẮNG!$J$6="","",CHỈ_SỐ_TRẮNG!$J$6+HỆ_SỐ_PHẨM_CHẤT!$I$7) -> 0.03 | K7: =IF(CHỈ_SỐ_TRẮNG!$K$6="","",CHỈ_SỐ_TRẮNG!$K$6+HỆ_SỐ_PHẨM_CHẤT!$J$7) -> 0.04 | L7: =IF(CHỈ_SỐ_TRẮNG!$L$6="","",CHỈ_SỐ_TRẮNG!$L$6+HỆ_SỐ_PHẨM_CHẤT!$K$7) -> 1.55 | M7: =IF(CHỈ_SỐ_TRẮNG!$M$6="","",CHỈ_SỐ_TRẮNG!$M$6+HỆ_SỐ_PHẨM_CHẤT!$L$7) -> 0.07 | N7: =IF(OR(N(I7)>0.1,N(K7)>0.1),"Né/chí mạng vượt 10%","")
A8: =NHÂN_VẬT!$A$6 -> NV01 | B8: =IF(NHÂN_VẬT!$B$6="","",NHÂN_VẬT!$B$6) -> HCM-THỦ KHO HIẾU | C8: =HỆ_SỐ_PHẨM_CHẤT!$A$8 -> Tím | D8: =IF(CHỈ_SỐ_TRẮNG!$D$6="","",ROUND(CHỈ_SỐ_TRẮNG!$D$6*HỆ_SỐ_PHẨM_CHẤT!$C$8,0)) -> 2250 | E8: =IF(CHỈ_SỐ_TRẮNG!$E$6="","",ROUND(CHỈ_SỐ_TRẮNG!$E$6*HỆ_SỐ_PHẨM_CHẤT!$D$8,0)) -> 98 | F8: =IF(CHỈ_SỐ_TRẮNG!$F$6="","",ROUND(CHỈ_SỐ_TRẮNG!$F$6*HỆ_SỐ_PHẨM_CHẤT!$E$8,0)) -> 96 | G8: =IF(CHỈ_SỐ_TRẮNG!$G$6="","",CHỈ_SỐ_TRẮNG!$G$6+HỆ_SỐ_PHẨM_CHẤT!$G$8) -> 91 | H8: =IF(CHỈ_SỐ_TRẮNG!$H$6="","",ROUND(CHỈ_SỐ_TRẮNG!$H$6*HỆ_SỐ_PHẨM_CHẤT!$F$8,1)) -> 36 | I8: =IF(CHỈ_SỐ_TRẮNG!$I$6="","",CHỈ_SỐ_TRẮNG!$I$6+HỆ_SỐ_PHẨM_CHẤT!$H$8) -> 0.035 | J8: =IF(CHỈ_SỐ_TRẮNG!$J$6="","",CHỈ_SỐ_TRẮNG!$J$6+HỆ_SỐ_PHẨM_CHẤT!$I$8) -> 0.035 | K8: =IF(CHỈ_SỐ_TRẮNG!$K$6="","",CHỈ_SỐ_TRẮNG!$K$6+HỆ_SỐ_PHẨM_CHẤT!$J$8) -> 0.045 | L8: =IF(CHỈ_SỐ_TRẮNG!$L$6="","",CHỈ_SỐ_TRẮNG!$L$6+HỆ_SỐ_PHẨM_CHẤT!$K$8) -> 1.6 | M8: =IF(CHỈ_SỐ_TRẮNG!$M$6="","",CHỈ_SỐ_TRẮNG!$M$6+HỆ_SỐ_PHẨM_CHẤT!$L$8) -> 0.075 | N8: =IF(OR(N(I8)>0.1,N(K8)>0.1),"Né/chí mạng vượt 10%","")
A9: =NHÂN_VẬT!$A$6 -> NV01 | B9: =IF(NHÂN_VẬT!$B$6="","",NHÂN_VẬT!$B$6) -> HCM-THỦ KHO HIẾU | C9: =HỆ_SỐ_PHẨM_CHẤT!$A$9 -> Đỏ | D9: =IF(CHỈ_SỐ_TRẮNG!$D$6="","",ROUND(CHỈ_SỐ_TRẮNG!$D$6*HỆ_SỐ_PHẨM_CHẤT!$C$9,0)) -> 2625 | E9: =IF(CHỈ_SỐ_TRẮNG!$E$6="","",ROUND(CHỈ_SỐ_TRẮNG!$E$6*HỆ_SỐ_PHẨM_CHẤT!$D$9,0)) -> 114 | F9: =IF(CHỈ_SỐ_TRẮNG!$F$6="","",ROUND(CHỈ_SỐ_TRẮNG!$F$6*HỆ_SỐ_PHẨM_CHẤT!$E$9,0)) -> 112 | G9: =IF(CHỈ_SỐ_TRẮNG!$G$6="","",CHỈ_SỐ_TRẮNG!$G$6+HỆ_SỐ_PHẨM_CHẤT!$G$9) -> 92 | H9: =IF(CHỈ_SỐ_TRẮNG!$H$6="","",ROUND(CHỈ_SỐ_TRẮNG!$H$6*HỆ_SỐ_PHẨM_CHẤT!$F$9,1)) -> 42 | I9: =IF(CHỈ_SỐ_TRẮNG!$I$6="","",CHỈ_SỐ_TRẮNG!$I$6+HỆ_SỐ_PHẨM_CHẤT!$H$9) -> 0.04 | J9: =IF(CHỈ_SỐ_TRẮNG!$J$6="","",CHỈ_SỐ_TRẮNG!$J$6+HỆ_SỐ_PHẨM_CHẤT!$I$9) -> 0.04 | K9: =IF(CHỈ_SỐ_TRẮNG!$K$6="","",CHỈ_SỐ_TRẮNG!$K$6+HỆ_SỐ_PHẨM_CHẤT!$J$9) -> 0.05 | L9: =IF(CHỈ_SỐ_TRẮNG!$L$6="","",CHỈ_SỐ_TRẮNG!$L$6+HỆ_SỐ_PHẨM_CHẤT!$K$9) -> 1.65 | M9: =IF(CHỈ_SỐ_TRẮNG!$M$6="","",CHỈ_SỐ_TRẮNG!$M$6+HỆ_SỐ_PHẨM_CHẤT!$L$9) -> 0.08 | N9: =IF(OR(N(I9)>0.1,N(K9)>0.1),"Né/chí mạng vượt 10%","")
A10: =NHÂN_VẬT!$A$7 -> NV02 | B10: =IF(NHÂN_VẬT!$B$7="","",NHÂN_VẬT!$B$7) -> HN-PHỤ KHO HƯNG | C10: =HỆ_SỐ_PHẨM_CHẤT!$A$5 -> Trắng | D10: =IF(CHỈ_SỐ_TRẮNG!$D$7="","",ROUND(CHỈ_SỐ_TRẮNG!$D$7*HỆ_SỐ_PHẨM_CHẤT!$C$5,0)) -> 1350 | E10: =IF(CHỈ_SỐ_TRẮNG!$E$7="","",ROUND(CHỈ_SỐ_TRẮNG!$E$7*HỆ_SỐ_PHẨM_CHẤT!$D$5,0)) -> 75 | F10: =IF(CHỈ_SỐ_TRẮNG!$F$7="","",ROUND(CHỈ_SỐ_TRẮNG!$F$7*HỆ_SỐ_PHẨM_CHẤT!$E$5,0)) -> 56 | G10: =IF(CHỈ_SỐ_TRẮNG!$G$7="","",CHỈ_SỐ_TRẮNG!$G$7+HỆ_SỐ_PHẨM_CHẤT!$G$5) -> 92 | H10: =IF(CHỈ_SỐ_TRẮNG!$H$7="","",ROUND(CHỈ_SỐ_TRẮNG!$H$7*HỆ_SỐ_PHẨM_CHẤT!$F$5,1)) -> 20 | I10: =IF(CHỈ_SỐ_TRẮNG!$I$7="","",CHỈ_SỐ_TRẮNG!$I$7+HỆ_SỐ_PHẨM_CHẤT!$H$5) -> 0.03 | J10: =IF(CHỈ_SỐ_TRẮNG!$J$7="","",CHỈ_SỐ_TRẮNG!$J$7+HỆ_SỐ_PHẨM_CHẤT!$I$5) -> 0.02 | K10: =IF(CHỈ_SỐ_TRẮNG!$K$7="","",CHỈ_SỐ_TRẮNG!$K$7+HỆ_SỐ_PHẨM_CHẤT!$J$5) -> 0.03 | L10: =IF(CHỈ_SỐ_TRẮNG!$L$7="","",CHỈ_SỐ_TRẮNG!$L$7+HỆ_SỐ_PHẨM_CHẤT!$K$5) -> 1.5 | M10: =IF(CHỈ_SỐ_TRẮNG!$M$7="","",CHỈ_SỐ_TRẮNG!$M$7+HỆ_SỐ_PHẨM_CHẤT!$L$5) -> 0.05 | N10: =IF(OR(N(I10)>0.1,N(K10)>0.1),"Né/chí mạng vượt 10%","")
